Workbook

Sheet 甘特圖
A1: 廖千儀 ♥ 陳郁諠 結婚籌備甘特圖
A2: 婚禮日期 → | C2: 46494 | D2: ← 修改 C2 日期，甘特圖列與 Checklist 到期日自動連動 | G2: =TODAY() -> 46168
A3: 圖例： | E3: 男方(廖千儀) | G3: 女方(陳郁諠) | I3: 雙方共同 | K3: 已完成 | M3: 今日欄 | O3: 婚禮月
A4: 類別 | B4: 項目 | C4: 負責 | D4: 2026 五月 | E4: 2026 六月 | F4: 2026 七月 | G4: 2026 八月 | H4: 2026 九月 | I4: 2026 十月 | J4: 2026 十一月 | K4: 2026 十二月 | L4: 2027 一月 | M4: 2027 二月 | N4: 2027 三月 | O4: 2027 四月 | P4: 2027 五月 | Q4: 2027 六月
A5: 確認規劃 | B5: 求婚完成 (04/17 已完成) | C5: 雙 | D5: =IF(AND(R5<=DATE(2026,5,1),S5>=DATE(2026,5,1)),IF(AND(MONTH(R5)=5,YEAR(R5)=2026),IF(AND(MONTH(S5)=5,YEAR(S5)=2026),"●","▶"),IF(AND(MONTH(S5)=5,YEAR(S5)=2026),"◀","─")),"") -> ● | E5: =IF(AND(R5<=DATE(2026,6,1),S5>=DATE(2026,6,1)),IF(AND(MONTH(R5)=6,YEAR(R5)=2026),IF(AND(MONTH(S5)=6,YEAR(S5)=2026),"●","▶"),IF(AND(MONTH(S5)=6,YEAR(S5)=2026),"◀","─")),"") | F5: =IF(AND(R5<=DATE(2026,7,1),S5>=DATE(2026,7,1)),IF(AND(MONTH(R5)=7,YEAR(R5)=2026),IF(AND(MONTH(S5)=7,YEAR(S5)=2026),"●","▶"),IF(AND(MONTH(S5)=7,YEAR(S5)=2026),"◀","─")),"") | G5: =IF(AND(R5<=DATE(2026,8,1),S5>=DATE(2026,8,1)),IF(AND(MONTH(R5)=8,YEAR(R5)=2026),IF(AND(MONTH(S5)=8,YEAR(S5)=2026),"●","▶"),IF(AND(MONTH(S5)=8,YEAR(S5)=2026),"◀","─")),"") | H5: =IF(AND(R5<=DATE(2026,9,1),S5>=DATE(2026,9,1)),IF(AND(MONTH(R5)=9,YEAR(R5)=2026),IF(AND(MONTH(S5)=9,YEAR(S5)=2026),"●","▶"),IF(AND(MONTH(S5)=9,YEAR(S5)=2026),"◀","─")),"") | I5: =IF(AND(R5<=DATE(2026,10,1),S5>=DATE(2026,10,1)),IF(AND(MONTH(R5)=10,YEAR(R5)=2026),IF(AND(MONTH(S5)=10,YEAR(S5)=2026),"●","▶"),IF(AND(MONTH(S5)=10,YEAR(S5)=2026),"◀","─")),"") | J5: =IF(AND(R5<=DATE(2026,11,1),S5>=DATE(2026,11,1)),IF(AND(MONTH(R5)=11,YEAR(R5)=2026),IF(AND(MONTH(S5)=11,YEAR(S5)=2026),"●","▶"),IF(AND(MONTH(S5)=11,YEAR(S5)=2026),"◀","─")),"") | K5: =IF(AND(R5<=DATE(2026,12,1),S5>=DATE(2026,12,1)),IF(AND(MONTH(R5)=12,YEAR(R5)=2026),IF(AND(MONTH(S5)=12,YEAR(S5)=2026),"●","▶"),IF(AND(MONTH(S5)=12,YEAR(S5)=2026),"◀","─")),"") | L5: =IF(AND(R5<=DATE(2027,1,1),S5>=DATE(2027,1,1)),IF(AND(MONTH(R5)=1,YEAR(R5)=2027),IF(AND(MONTH(S5)=1,YEAR(S5)=2027),"●","▶"),IF(AND(MONTH(S5)=1,YEAR(S5)=2027),"◀","─")),"") | M5: =IF(AND(R5<=DATE(2027,2,1),S5>=DATE(2027,2,1)),IF(AND(MONTH(R5)=2,YEAR(R5)=2027),IF(AND(MONTH(S5)=2,YEAR(S5)=2027),"●","▶"),IF(AND(MONTH(S5)=2,YEAR(S5)=2027),"◀","─")),"") | N5: =IF(AND(R5<=DATE(2027,3,1),S5>=DATE(2027,3,1)),IF(AND(MONTH(R5)=3,YEAR(R5)=2027),IF(AND(MONTH(S5)=3,YEAR(S5)=2027),"●","▶"),IF(AND(MONTH(S5)=3,YEAR(S5)=2027),"◀","─")),"") | O5: =IF(AND(R5<=DATE(2027,4,1),S5>=DATE(2027,4,1)),IF(AND(MONTH(R5)=4,YEAR(R5)=2027),IF(AND(MONTH(S5)=4,YEAR(S5)=2027),"●","▶"),IF(AND(MONTH(S5)=4,YEAR(S5)=2027),"◀","─")),"") | P5: =IF(AND(R5<=DATE(2027,5,1),S5>=DATE(2027,5,1)),IF(AND(MONTH(R5)=5,YEAR(R5)=2027),IF(AND(MONTH(S5)=5,YEAR(S5)=2027),"●","▶"),IF(AND(MONTH(S5)=5,YEAR(S5)=2027),"◀","─")),"") | Q5: =IF(AND(R5<=DATE(2027,6,1),S5>=DATE(2027,6,1)),IF(AND(MONTH(R5)=6,YEAR(R5)=2027),IF(AND(MONTH(S5)=6,YEAR(S5)=2027),"●","▶"),IF(AND(MONTH(S5)=6,YEAR(S5)=2027),"◀","─")),"") | R5: 46143 | S5: 46143 | T5: 4
B6: 家長面談 (05/30 已排定) | C6: 雙 | D6: =IF(AND(R6<=DATE(2026,5,1),S6>=DATE(2026,5,1)),IF(AND(MONTH(R6)=5,YEAR(R6)=2026),IF(AND(MONTH(S6)=5,YEAR(S6)=2026),"●","▶"),IF(AND(MONTH(S6)=5,YEAR(S6)=2026),"◀","─")),"") -> ● | E6: =IF(AND(R6<=DATE(2026,6,1),S6>=DATE(2026,6,1)),IF(AND(MONTH(R6)=6,YEAR(R6)=2026),IF(AND(MONTH(S6)=6,YEAR(S6)=2026),"●","▶"),IF(AND(MONTH(S6)=6,YEAR(S6)=2026),"◀","─")),"") | F6: =IF(AND(R6<=DATE(2026,7,1),S6>=DATE(2026,7,1)),IF(AND(MONTH(R6)=7,YEAR(R6)=2026),IF(AND(MONTH(S6)=7,YEAR(S6)=2026),"●","▶"),IF(AND(MONTH(S6)=7,YEAR(S6)=2026),"◀","─")),"") | G6: =IF(AND(R6<=DATE(2026,8,1),S6>=DATE(2026,8,1)),IF(AND(MONTH(R6)=8,YEAR(R6)=2026),IF(AND(MONTH(S6)=8,YEAR(S6)=2026),"●","▶"),IF(AND(MONTH(S6)=8,YEAR(S6)=2026),"◀","─")),"") | H6: =IF(AND(R6<=DATE(2026,9,1),S6>=DATE(2026,9,1)),IF(AND(MONTH(R6)=9,YEAR(R6)=2026),IF(AND(MONTH(S6)=9,YEAR(S6)=2026),"●","▶"),IF(AND(MONTH(S6)=9,YEAR(S6)=2026),"◀","─")),"") | I6: =IF(AND(R6<=DATE(2026,10,1),S6>=DATE(2026,10,1)),IF(AND(MONTH(R6)=10,YEAR(R6)=2026),IF(AND(MONTH(S6)=10,YEAR(S6)=2026),"●","▶"),IF(AND(MONTH(S6)=10,YEAR(S6)=2026),"◀","─")),"") | J6: =IF(AND(R6<=DATE(2026,11,1),S6>=DATE(2026,11,1)),IF(AND(MONTH(R6)=11,YEAR(R6)=2026),IF(AND(MONTH(S6)=11,YEAR(S6)=2026),"●","▶"),IF(AND(MONTH(S6)=11,YEAR(S6)=2026),"◀","─")),"") | K6: =IF(AND(R6<=DATE(2026,12,1),S6>=DATE(2026,12,1)),IF(AND(MONTH(R6)=12,YEAR(R6)=2026),IF(AND(MONTH(S6)=12,YEAR(S6)=2026),"●","▶"),IF(AND(MONTH(S6)=12,YEAR(S6)=2026),"◀","─")),"") | L6: =IF(AND(R6<=DATE(2027,1,1),S6>=DATE(2027,1,1)),IF(AND(MONTH(R6)=1,YEAR(R6)=2027),IF(AND(MONTH(S6)=1,YEAR(S6)=2027),"●","▶"),IF(AND(MONTH(S6)=1,YEAR(S6)=2027),"◀","─")),"") | M6: =IF(AND(R6<=DATE(2027,2,1),S6>=DATE(2027,2,1)),IF(AND(MONTH(R6)=2,YEAR(R6)=2027),IF(AND(MONTH(S6)=2,YEAR(S6)=2027),"●","▶"),IF(AND(MONTH(S6)=2,YEAR(S6)=2027),"◀","─")),"") | N6: =IF(AND(R6<=DATE(2027,3,1),S6>=DATE(2027,3,1)),IF(AND(MONTH(R6)=3,YEAR(R6)=2027),IF(AND(MONTH(S6)=3,YEAR(S6)=2027),"●","▶"),IF(AND(MONTH(S6)=3,YEAR(S6)=2027),"◀","─")),"") | O6: =IF(AND(R6<=DATE(2027,4,1),S6>=DATE(2027,4,1)),IF(AND(MONTH(R6)=4,YEAR(R6)=2027),IF(AND(MONTH(S6)=4,YEAR(S6)=2027),"●","▶"),IF(AND(MONTH(S6)=4,YEAR(S6)=2027),"◀","─")),"") | P6: =IF(AND(R6<=DATE(2027,5,1),S6>=DATE(2027,5,1)),IF(AND(MONTH(R6)=5,YEAR(R6)=2027),IF(AND(MONTH(S6)=5,YEAR(S6)=2027),"●","▶"),IF(AND(MONTH(S6)=5,YEAR(S6)=2027),"◀","─")),"") | Q6: =IF(AND(R6<=DATE(2027,6,1),S6>=DATE(2027,6,1)),IF(AND(MONTH(R6)=6,YEAR(R6)=2027),IF(AND(MONTH(S6)=6,YEAR(S6)=2027),"●","▶"),IF(AND(MONTH(S6)=6,YEAR(S6)=2027),"◀","─")),"") | R6: 46143 | S6: 46143 | T6: 4
B7: 確定婚禮日期（查農民曆） | C7: 雙 | D7: =IF(AND(R7<=DATE(2026,5,1),S7>=DATE(2026,5,1)),IF(AND(MONTH(R7)=5,YEAR(R7)=2026),IF(AND(MONTH(S7)=5,YEAR(S7)=2026),"●","▶"),IF(AND(MONTH(S7)=5,YEAR(S7)=2026),"◀","─")),"") | E7: =IF(AND(R7<=DATE(2026,6,1),S7>=DATE(2026,6,1)),IF(AND(MONTH(R7)=6,YEAR(R7)=2026),IF(AND(MONTH(S7)=6,YEAR(S7)=2026),"●","▶"),IF(AND(MONTH(S7)=6,YEAR(S7)=2026),"◀","─")),"") | F7: =IF(AND(R7<=DATE(2026,7,1),S7>=DATE(2026,7,1)),IF(AND(MONTH(R7)=7,YEAR(R7)=2026),IF(AND(MONTH(S7)=7,YEAR(S7)=2026),"●","▶"),IF(AND(MONTH(S7)=7,YEAR(S7)=2026),"◀","─")),"") | G7: =IF(AND(R7<=DATE(2026,8,1),S7>=DATE(2026,8,1)),IF(AND(MONTH(R7)=8,YEAR(R7)=2026),IF(AND(MONTH(S7)=8,YEAR(S7)=2026),"●","▶"),IF(AND(MONTH(S7)=8,YEAR(S7)=2026),"◀","─")),"") | H7: =IF(AND(R7<=DATE(2026,9,1),S7>=DATE(2026,9,1)),IF(AND(MONTH(R7)=9,YEAR(R7)=2026),IF(AND(MONTH(S7)=9,YEAR(S7)=2026),"●","▶"),IF(AND(MONTH(S7)=9,YEAR(S7)=2026),"◀","─")),"") | I7: =IF(AND(R7<=DATE(2026,10,1),S7>=DATE(2026,10,1)),IF(AND(MONTH(R7)=10,YEAR(R7)=2026),IF(AND(MONTH(S7)=10,YEAR(S7)=2026),"●","▶"),IF(AND(MONTH(S7)=10,YEAR(S7)=2026),"◀","─")),"") -> ◀ | J7: =IF(AND(R7<=DATE(2026,11,1),S7>=DATE(2026,11,1)),IF(AND(MONTH(R7)=11,YEAR(R7)=2026),IF(AND(MONTH(S7)=11,YEAR(S7)=2026),"●","▶"),IF(AND(MONTH(S7)=11,YEAR(S7)=2026),"◀","─")),"") | K7: =IF(AND(R7<=DATE(2026,12,1),S7>=DATE(2026,12,1)),IF(AND(MONTH(R7)=12,YEAR(R7)=2026),IF(AND(MONTH(S7)=12,YEAR(S7)=2026),"●","▶"),IF(AND(MONTH(S7)=12,YEAR(S7)=2026),"◀","─")),"") | L7: =IF(AND(R7<=DATE(2027,1,1),S7>=DATE(2027,1,1)),IF(AND(MONTH(R7)=1,YEAR(R7)=2027),IF(AND(MONTH(S7)=1,YEAR(S7)=2027),"●","▶"),IF(AND(MONTH(S7)=1,YEAR(S7)=2027),"◀","─")),"") | M7: =IF(AND(R7<=DATE(2027,2,1),S7>=DATE(2027,2,1)),IF(AND(MONTH(R7)=2,YEAR(R7)=2027),IF(AND(MONTH(S7)=2,YEAR(S7)=2027),"●","▶"),IF(AND(MONTH(S7)=2,YEAR(S7)=2027),"◀","─")),"") | N7: =IF(AND(R7<=DATE(2027,3,1),S7>=DATE(2027,3,1)),IF(AND(MONTH(R7)=3,YEAR(R7)=2027),IF(AND(MONTH(S7)=3,YEAR(S7)=2027),"●","▶"),IF(AND(MONTH(S7)=3,YEAR(S7)=2027),"◀","─")),"") | O7: =IF(AND(R7<=DATE(2027,4,1),S7>=DATE(2027,4,1)),IF(AND(MONTH(R7)=4,YEAR(R7)=2027),IF(AND(MONTH(S7)=4,YEAR(S7)=2027),"●","▶"),IF(AND(MONTH(S7)=4,YEAR(S7)=2027),"◀","─")),"") | P7: =IF(AND(R7<=DATE(2027,5,1),S7>=DATE(2027,5,1)),IF(AND(MONTH(R7)=5,YEAR(R7)=2027),IF(AND(MONTH(S7)=5,YEAR(S7)=2027),"●","▶"),IF(AND(MONTH(S7)=5,YEAR(S7)=2027),"◀","─")),"") | Q7: =IF(AND(R7<=DATE(2027,6,1),S7>=DATE(2027,6,1)),IF(AND(MONTH(R7)=6,YEAR(R7)=2027),IF(AND(MONTH(S7)=6,YEAR(S7)=2027),"●","▶"),IF(AND(MONTH(S7)=6,YEAR(S7)=2027),"◀","─")),"") | R7: =EDATE($C$2,-7) -> 46282 | S7: =EDATE($C$2,-6) -> 46312 | T7: 3
B8: 確認婚禮總預算 | C8: 雙 | D8: =IF(AND(R8<=DATE(2026,5,1),S8>=DATE(2026,5,1)),IF(AND(MONTH(R8)=5,YEAR(R8)=2026),IF(AND(MONTH(S8)=5,YEAR(S8)=2026),"●","▶"),IF(AND(MONTH(S8)=5,YEAR(S8)=2026),"◀","─")),"") | E8: =IF(AND(R8<=DATE(2026,6,1),S8>=DATE(2026,6,1)),IF(AND(MONTH(R8)=6,YEAR(R8)=2026),IF(AND(MONTH(S8)=6,YEAR(S8)=2026),"●","▶"),IF(AND(MONTH(S8)=6,YEAR(S8)=2026),"◀","─")),"") | F8: =IF(AND(R8<=DATE(2026,7,1),S8>=DATE(2026,7,1)),IF(AND(MONTH(R8)=7,YEAR(R8)=2026),IF(AND(MONTH(S8)=7,YEAR(S8)=2026),"●","▶"),IF(AND(MONTH(S8)=7,YEAR(S8)=2026),"◀","─")),"") | G8: =IF(AND(R8<=DATE(2026,8,1),S8>=DATE(2026,8,1)),IF(AND(MONTH(R8)=8,YEAR(R8)=2026),IF(AND(MONTH(S8)=8,YEAR(S8)=2026),"●","▶"),IF(AND(MONTH(S8)=8,YEAR(S8)=2026),"◀","─")),"") | H8: =IF(AND(R8<=DATE(2026,9,1),S8>=DATE(2026,9,1)),IF(AND(MONTH(R8)=9,YEAR(R8)=2026),IF(AND(MONTH(S8)=9,YEAR(S8)=2026),"●","▶"),IF(AND(MONTH(S8)=9,YEAR(S8)=2026),"◀","─")),"") | I8: =IF(AND(R8<=DATE(2026,10,1),S8>=DATE(2026,10,1)),IF(AND(MONTH(R8)=10,YEAR(R8)=2026),IF(AND(MONTH(S8)=10,YEAR(S8)=2026),"●","▶"),IF(AND(MONTH(S8)=10,YEAR(S8)=2026),"◀","─")),"") -> ◀ | J8: =IF(AND(R8<=DATE(2026,11,1),S8>=DATE(2026,11,1)),IF(AND(MONTH(R8)=11,YEAR(R8)=2026),IF(AND(MONTH(S8)=11,YEAR(S8)=2026),"●","▶"),IF(AND(MONTH(S8)=11,YEAR(S8)=2026),"◀","─")),"") | K8: =IF(AND(R8<=DATE(2026,12,1),S8>=DATE(2026,12,1)),IF(AND(MONTH(R8)=12,YEAR(R8)=2026),IF(AND(MONTH(S8)=12,YEAR(S8)=2026),"●","▶"),IF(AND(MONTH(S8)=12,YEAR(S8)=2026),"◀","─")),"") | L8: =IF(AND(R8<=DATE(2027,1,1),S8>=DATE(2027,1,1)),IF(AND(MONTH(R8)=1,YEAR(R8)=2027),IF(AND(MONTH(S8)=1,YEAR(S8)=2027),"●","▶"),IF(AND(MONTH(S8)=1,YEAR(S8)=2027),"◀","─")),"") | M8: =IF(AND(R8<=DATE(2027,2,1),S8>=DATE(2027,2,1)),IF(AND(MONTH(R8)=2,YEAR(R8)=2027),IF(AND(MONTH(S8)=2,YEAR(S8)=2027),"●","▶"),IF(AND(MONTH(S8)=2,YEAR(S8)=2027),"◀","─")),"") | N8: =IF(AND(R8<=DATE(2027,3,1),S8>=DATE(2027,3,1)),IF(AND(MONTH(R8)=3,YEAR(R8)=2027),IF(AND(MONTH(S8)=3,YEAR(S8)=2027),"●","▶"),IF(AND(MONTH(S8)=3,YEAR(S8)=2027),"◀","─")),"") | O8: =IF(AND(R8<=DATE(2027,4,1),S8>=DATE(2027,4,1)),IF(AND(MONTH(R8)=4,YEAR(R8)=2027),IF(AND(MONTH(S8)=4,YEAR(S8)=2027),"●","▶"),IF(AND(MONTH(S8)=4,YEAR(S8)=2027),"◀","─")),"") | P8: =IF(AND(R8<=DATE(2027,5,1),S8>=DATE(2027,5,1)),IF(AND(MONTH(R8)=5,YEAR(R8)=2027),IF(AND(MONTH(S8)=5,YEAR(S8)=2027),"●","▶"),IF(AND(MONTH(S8)=5,YEAR(S8)=2027),"◀","─")),"") | Q8: =IF(AND(R8<=DATE(2027,6,1),S8>=DATE(2027,6,1)),IF(AND(MONTH(R8)=6,YEAR(R8)=2027),IF(AND(MONTH(S8)=6,YEAR(S8)=2027),"●","▶"),IF(AND(MONTH(S8)=6,YEAR(S8)=2027),"◀","─")),"") | R8: =EDATE($C$2,-7) -> 46282 | S8: =EDATE($C$2,-6) -> 46312 | T8: 3
B9: 確認賓客名單初稿 | C9: 雙 | D9: =IF(AND(R9<=DATE(2026,5,1),S9>=DATE(2026,5,1)),IF(AND(MONTH(R9)=5,YEAR(R9)=2026),IF(AND(MONTH(S9)=5,YEAR(S9)=2026),"●","▶"),IF(AND(MONTH(S9)=5,YEAR(S9)=2026),"◀","─")),"") | E9: =IF(AND(R9<=DATE(2026,6,1),S9>=DATE(2026,6,1)),IF(AND(MONTH(R9)=6,YEAR(R9)=2026),IF(AND(MONTH(S9)=6,YEAR(S9)=2026),"●","▶"),IF(AND(MONTH(S9)=6,YEAR(S9)=2026),"◀","─")),"") | F9: =IF(AND(R9<=DATE(2026,7,1),S9>=DATE(2026,7,1)),IF(AND(MONTH(R9)=7,YEAR(R9)=2026),IF(AND(MONTH(S9)=7,YEAR(S9)=2026),"●","▶"),IF(AND(MONTH(S9)=7,YEAR(S9)=2026),"◀","─")),"") | G9: =IF(AND(R9<=DATE(2026,8,1),S9>=DATE(2026,8,1)),IF(AND(MONTH(R9)=8,YEAR(R9)=2026),IF(AND(MONTH(S9)=8,YEAR(S9)=2026),"●","▶"),IF(AND(MONTH(S9)=8,YEAR(S9)=2026),"◀","─")),"") | H9: =IF(AND(R9<=DATE(2026,9,1),S9>=DATE(2026,9,1)),IF(AND(MONTH(R9)=9,YEAR(R9)=2026),IF(AND(MONTH(S9)=9,YEAR(S9)=2026),"●","▶"),IF(AND(MONTH(S9)=9,YEAR(S9)=2026),"◀","─")),"") | I9: =IF(AND(R9<=DATE(2026,10,1),S9>=DATE(2026,10,1)),IF(AND(MONTH(R9)=10,YEAR(R9)=2026),IF(AND(MONTH(S9)=10,YEAR(S9)=2026),"●","▶"),IF(AND(MONTH(S9)=10,YEAR(S9)=2026),"◀","─")),"") | J9: =IF(AND(R9<=DATE(2026,11,1),S9>=DATE(2026,11,1)),IF(AND(MONTH(R9)=11,YEAR(R9)=2026),IF(AND(MONTH(S9)=11,YEAR(S9)=2026),"●","▶"),IF(AND(MONTH(S9)=11,YEAR(S9)=2026),"◀","─")),"") -> ◀ | K9: =IF(AND(R9<=DATE(2026,12,1),S9>=DATE(2026,12,1)),IF(AND(MONTH(R9)=12,YEAR(R9)=2026),IF(AND(MONTH(S9)=12,YEAR(S9)=2026),"●","▶"),IF(AND(MONTH(S9)=12,YEAR(S9)=2026),"◀","─")),"") | L9: =IF(AND(R9<=DATE(2027,1,1),S9>=DATE(2027,1,1)),IF(AND(MONTH(R9)=1,YEAR(R9)=2027),IF(AND(MONTH(S9)=1,YEAR(S9)=2027),"●","▶"),IF(AND(MONTH(S9)=1,YEAR(S9)=2027),"◀","─")),"") | M9: =IF(AND(R9<=DATE(2027,2,1),S9>=DATE(2027,2,1)),IF(AND(MONTH(R9)=2,YEAR(R9)=2027),IF(AND(MONTH(S9)=2,YEAR(S9)=2027),"●","▶"),IF(AND(MONTH(S9)=2,YEAR(S9)=2027),"◀","─")),"") | N9: =IF(AND(R9<=DATE(2027,3,1),S9>=DATE(2027,3,1)),IF(AND(MONTH(R9)=3,YEAR(R9)=2027),IF(AND(MONTH(S9)=3,YEAR(S9)=2027),"●","▶"),IF(AND(MONTH(S9)=3,YEAR(S9)=2027),"◀","─")),"") | O9: =IF(AND(R9<=DATE(2027,4,1),S9>=DATE(2027,4,1)),IF(AND(MONTH(R9)=4,YEAR(R9)=2027),IF(AND(MONTH(S9)=4,YEAR(S9)=2027),"●","▶"),IF(AND(MONTH(S9)=4,YEAR(S9)=2027),"◀","─")),"") | P9: =IF(AND(R9<=DATE(2027,5,1),S9>=DATE(2027,5,1)),IF(AND(MONTH(R9)=5,YEAR(R9)=2027),IF(AND(MONTH(S9)=5,YEAR(S9)=2027),"●","▶"),IF(AND(MONTH(S9)=5,YEAR(S9)=2027),"◀","─")),"") | Q9: =IF(AND(R9<=DATE(2027,6,1),S9>=DATE(2027,6,1)),IF(AND(MONTH(R9)=6,YEAR(R9)=2027),IF(AND(MONTH(S9)=6,YEAR(S9)=2027),"●","▶"),IF(AND(MONTH(S9)=6,YEAR(S9)=2027),"◀","─")),"") | R9: =EDATE($C$2,-6) -> 46312 | S9: =EDATE($C$2,-5) -> 46343 | T9: 3
B10: 確定婚宴形式（飯店/餐廳） | C10: 雙 | D10: =IF(AND(R10<=DATE(2026,5,1),S10>=DATE(2026,5,1)),IF(AND(MONTH(R10)=5,YEAR(R10)=2026),IF(AND(MONTH(S10)=5,YEAR(S10)=2026),"●","▶"),IF(AND(MONTH(S10)=5,YEAR(S10)=2026),"◀","─")),"") | E10: =IF(AND(R10<=DATE(2026,6,1),S10>=DATE(2026,6,1)),IF(AND(MONTH(R10)=6,YEAR(R10)=2026),IF(AND(MONTH(S10)=6,YEAR(S10)=2026),"●","▶"),IF(AND(MONTH(S10)=6,YEAR(S10)=2026),"◀","─")),"") | F10: =IF(AND(R10<=DATE(2026,7,1),S10>=DATE(2026,7,1)),IF(AND(MONTH(R10)=7,YEAR(R10)=2026),IF(AND(MONTH(S10)=7,YEAR(S10)=2026),"●","▶"),IF(AND(MONTH(S10)=7,YEAR(S10)=2026),"◀","─")),"") | G10: =IF(AND(R10<=DATE(2026,8,1),S10>=DATE(2026,8,1)),IF(AND(MONTH(R10)=8,YEAR(R10)=2026),IF(AND(MONTH(S10)=8,YEAR(S10)=2026),"●","▶"),IF(AND(MONTH(S10)=8,YEAR(S10)=2026),"◀","─")),"") | H10: =IF(AND(R10<=DATE(2026,9,1),S10>=DATE(2026,9,1)),IF(AND(MONTH(R10)=9,YEAR(R10)=2026),IF(AND(MONTH(S10)=9,YEAR(S10)=2026),"●","▶"),IF(AND(MONTH(S10)=9,YEAR(S10)=2026),"◀","─")),"") | I10: =IF(AND(R10<=DATE(2026,10,1),S10>=DATE(2026,10,1)),IF(AND(MONTH(R10)=10,YEAR(R10)=2026),IF(AND(MONTH(S10)=10,YEAR(S10)=2026),"●","▶"),IF(AND(MONTH(S10)=10,YEAR(S10)=2026),"◀","─")),"") -> ◀ | J10: =IF(AND(R10<=DATE(2026,11,1),S10>=DATE(2026,11,1)),IF(AND(MONTH(R10)=11,YEAR(R10)=2026),IF(AND(MONTH(S10)=11,YEAR(S10)=2026),"●","▶"),IF(AND(MONTH(S10)=11,YEAR(S10)=2026),"◀","─")),"") | K10: =IF(AND(R10<=DATE(2026,12,1),S10>=DATE(2026,12,1)),IF(AND(MONTH(R10)=12,YEAR(R10)=2026),IF(AND(MONTH(S10)=12,YEAR(S10)=2026),"●","▶"),IF(AND(MONTH(S10)=12,YEAR(S10)=2026),"◀","─")),"") | L10: =IF(AND(R10<=DATE(2027,1,1),S10>=DATE(2027,1,1)),IF(AND(MONTH(R10)=1,YEAR(R10)=2027),IF(AND(MONTH(S10)=1,YEAR(S10)=2027),"●","▶"),IF(AND(MONTH(S10)=1,YEAR(S10)=2027),"◀","─")),"") | M10: =IF(AND(R10<=DATE(2027,2,1),S10>=DATE(2027,2,1)),IF(AND(MONTH(R10)=2,YEAR(R10)=2027),IF(AND(MONTH(S10)=2,YEAR(S10)=2027),"●","▶"),IF(AND(MONTH(S10)=2,YEAR(S10)=2027),"◀","─")),"") | N10: =IF(AND(R10<=DATE(2027,3,1),S10>=DATE(2027,3,1)),IF(AND(MONTH(R10)=3,YEAR(R10)=2027),IF(AND(MONTH(S10)=3,YEAR(S10)=2027),"●","▶"),IF(AND(MONTH(S10)=3,YEAR(S10)=2027),"◀","─")),"") | O10: =IF(AND(R10<=DATE(2027,4,1),S10>=DATE(2027,4,1)),IF(AND(MONTH(R10)=4,YEAR(R10)=2027),IF(AND(MONTH(S10)=4,YEAR(S10)=2027),"●","▶"),IF(AND(MONTH(S10)=4,YEAR(S10)=2027),"◀","─")),"") | P10: =IF(AND(R10<=DATE(2027,5,1),S10>=DATE(2027,5,1)),IF(AND(MONTH(R10)=5,YEAR(R10)=2027),IF(AND(MONTH(S10)=5,YEAR(S10)=2027),"●","▶"),IF(AND(MONTH(S10)=5,YEAR(S10)=2027),"◀","─")),"") | Q10: =IF(AND(R10<=DATE(2027,6,1),S10>=DATE(2027,6,1)),IF(AND(MONTH(R10)=6,YEAR(R10)=2027),IF(AND(MONTH(S10)=6,YEAR(S10)=2027),"●","▶"),IF(AND(MONTH(S10)=6,YEAR(S10)=2027),"◀","─")),"") | R10: =EDATE($C$2,-7) -> 46282 | S10: =EDATE($C$2,-6) -> 46312 | T10: 3
A11: 預訂服務 | B11: 預訂婚宴場地 ⚡ | C11: 雙 | D11: =IF(AND(R11<=DATE(2026,5,1),S11>=DATE(2026,5,1)),IF(AND(MONTH(R11)=5,YEAR(R11)=2026),IF(AND(MONTH(S11)=5,YEAR(S11)=2026),"●","▶"),IF(AND(MONTH(S11)=5,YEAR(S11)=2026),"◀","─")),"") | E11: =IF(AND(R11<=DATE(2026,6,1),S11>=DATE(2026,6,1)),IF(AND(MONTH(R11)=6,YEAR(R11)=2026),IF(AND(MONTH(S11)=6,YEAR(S11)=2026),"●","▶"),IF(AND(MONTH(S11)=6,YEAR(S11)=2026),"◀","─")),"") | F11: =IF(AND(R11<=DATE(2026,7,1),S11>=DATE(2026,7,1)),IF(AND(MONTH(R11)=7,YEAR(R11)=2026),IF(AND(MONTH(S11)=7,YEAR(S11)=2026),"●","▶"),IF(AND(MONTH(S11)=7,YEAR(S11)=2026),"◀","─")),"") -> ─ | G11: =IF(AND(R11<=DATE(2026,8,1),S11>=DATE(2026,8,1)),IF(AND(MONTH(R11)=8,YEAR(R11)=2026),IF(AND(MONTH(S11)=8,YEAR(S11)=2026),"●","▶"),IF(AND(MONTH(S11)=8,YEAR(S11)=2026),"◀","─")),"") -> ◀ | H11: =IF(AND(R11<=DATE(2026,9,1),S11>=DATE(2026,9,1)),IF(AND(MONTH(R11)=9,YEAR(R11)=2026),IF(AND(MONTH(S11)=9,YEAR(S11)=2026),"●","▶"),IF(AND(MONTH(S11)=9,YEAR(S11)=2026),"◀","─")),"") | I11: =IF(AND(R11<=DATE(2026,10,1),S11>=DATE(2026,10,1)),IF(AND(MONTH(R11)=10,YEAR(R11)=2026),IF(AND(MONTH(S11)=10,YEAR(S11)=2026),"●","▶"),IF(AND(MONTH(S11)=10,YEAR(S11)=2026),"◀","─")),"") | J11: =IF(AND(R11<=DATE(2026,11,1),S11>=DATE(2026,11,1)),IF(AND(MONTH(R11)=11,YEAR(R11)=2026),IF(AND(MONTH(S11)=11,YEAR(S11)=2026),"●","▶"),IF(AND(MONTH(S11)=11,YEAR(S11)=2026),"◀","─")),"") | K11: =IF(AND(R11<=DATE(2026,12,1),S11>=DATE(2026,12,1)),IF(AND(MONTH(R11)=12,YEAR(R11)=2026),IF(AND(MONTH(S11)=12,YEAR(S11)=2026),"●","▶"),IF(AND(MONTH(S11)=12,YEAR(S11)=2026),"◀","─")),"") | L11: =IF(AND(R11<=DATE(2027,1,1),S11>=DATE(2027,1,1)),IF(AND(MONTH(R11)=1,YEAR(R11)=2027),IF(AND(MONTH(S11)=1,YEAR(S11)=2027),"●","▶"),IF(AND(MONTH(S11)=1,YEAR(S11)=2027),"◀","─")),"") | M11: =IF(AND(R11<=DATE(2027,2,1),S11>=DATE(2027,2,1)),IF(AND(MONTH(R11)=2,YEAR(R11)=2027),IF(AND(MONTH(S11)=2,YEAR(S11)=2027),"●","▶"),IF(AND(MONTH(S11)=2,YEAR(S11)=2027),"◀","─")),"") | N11: =IF(AND(R11<=DATE(2027,3,1),S11>=DATE(2027,3,1)),IF(AND(MONTH(R11)=3,YEAR(R11)=2027),IF(AND(MONTH(S11)=3,YEAR(S11)=2027),"●","▶"),IF(AND(MONTH(S11)=3,YEAR(S11)=2027),"◀","─")),"") | O11: =IF(AND(R11<=DATE(2027,4,1),S11>=DATE(2027,4,1)),IF(AND(MONTH(R11)=4,YEAR(R11)=2027),IF(AND(MONTH(S11)=4,YEAR(S11)=2027),"●","▶"),IF(AND(MONTH(S11)=4,YEAR(S11)=2027),"◀","─")),"") | P11: =IF(AND(R11<=DATE(2027,5,1),S11>=DATE(2027,5,1)),IF(AND(MONTH(R11)=5,YEAR(R11)=2027),IF(AND(MONTH(S11)=5,YEAR(S11)=2027),"●","▶"),IF(AND(MONTH(S11)=5,YEAR(S11)=2027),"◀","─")),"") | Q11: =IF(AND(R11<=DATE(2027,6,1),S11>=DATE(2027,6,1)),IF(AND(MONTH(R11)=6,YEAR(R11)=2027),IF(AND(MONTH(S11)=6,YEAR(S11)=2027),"●","▶"),IF(AND(MONTH(S11)=6,YEAR(S11)=2027),"◀","─")),"") | R11: =EDATE('完整 Checklist'!F11,-1) -> 46203 | S11: =EDATE($R$11,2) -> 46264 | T11: 3
B12: 預訂婚紗工作室 | C12: 雙 | D12: =IF(AND(R12<=DATE(2026,5,1),S12>=DATE(2026,5,1)),IF(AND(MONTH(R12)=5,YEAR(R12)=2026),IF(AND(MONTH(S12)=5,YEAR(S12)=2026),"●","▶"),IF(AND(MONTH(S12)=5,YEAR(S12)=2026),"◀","─")),"") | E12: =IF(AND(R12<=DATE(2026,6,1),S12>=DATE(2026,6,1)),IF(AND(MONTH(R12)=6,YEAR(R12)=2026),IF(AND(MONTH(S12)=6,YEAR(S12)=2026),"●","▶"),IF(AND(MONTH(S12)=6,YEAR(S12)=2026),"◀","─")),"") | F12: =IF(AND(R12<=DATE(2026,7,1),S12>=DATE(2026,7,1)),IF(AND(MONTH(R12)=7,YEAR(R12)=2026),IF(AND(MONTH(S12)=7,YEAR(S12)=2026),"●","▶"),IF(AND(MONTH(S12)=7,YEAR(S12)=2026),"◀","─")),"") | G12: =IF(AND(R12<=DATE(2026,8,1),S12>=DATE(2026,8,1)),IF(AND(MONTH(R12)=8,YEAR(R12)=2026),IF(AND(MONTH(S12)=8,YEAR(S12)=2026),"●","▶"),IF(AND(MONTH(S12)=8,YEAR(S12)=2026),"◀","─")),"") | H12: =IF(AND(R12<=DATE(2026,9,1),S12>=DATE(2026,9,1)),IF(AND(MONTH(R12)=9,YEAR(R12)=2026),IF(AND(MONTH(S12)=9,YEAR(S12)=2026),"●","▶"),IF(AND(MONTH(S12)=9,YEAR(S12)=2026),"◀","─")),"") | I12: =IF(AND(R12<=DATE(2026,10,1),S12>=DATE(2026,10,1)),IF(AND(MONTH(R12)=10,YEAR(R12)=2026),IF(AND(MONTH(S12)=10,YEAR(S12)=2026),"●","▶"),IF(AND(MONTH(S12)=10,YEAR(S12)=2026),"◀","─")),"") | J12: =IF(AND(R12<=DATE(2026,11,1),S12>=DATE(2026,11,1)),IF(AND(MONTH(R12)=11,YEAR(R12)=2026),IF(AND(MONTH(S12)=11,YEAR(S12)=2026),"●","▶"),IF(AND(MONTH(S12)=11,YEAR(S12)=2026),"◀","─")),"") -> ─ | K12: =IF(AND(R12<=DATE(2026,12,1),S12>=DATE(2026,12,1)),IF(AND(MONTH(R12)=12,YEAR(R12)=2026),IF(AND(MONTH(S12)=12,YEAR(S12)=2026),"●","▶"),IF(AND(MONTH(S12)=12,YEAR(S12)=2026),"◀","─")),"") -> ◀ | L12: =IF(AND(R12<=DATE(2027,1,1),S12>=DATE(2027,1,1)),IF(AND(MONTH(R12)=1,YEAR(R12)=2027),IF(AND(MONTH(S12)=1,YEAR(S12)=2027),"●","▶"),IF(AND(MONTH(S12)=1,YEAR(S12)=2027),"◀","─")),"") | M12: =IF(AND(R12<=DATE(2027,2,1),S12>=DATE(2027,2,1)),IF(AND(MONTH(R12)=2,YEAR(R12)=2027),IF(AND(MONTH(S12)=2,YEAR(S12)=2027),"●","▶"),IF(AND(MONTH(S12)=2,YEAR(S12)=2027),"◀","─")),"") | N12: =IF(AND(R12<=DATE(2027,3,1),S12>=DATE(2027,3,1)),IF(AND(MONTH(R12)=3,YEAR(R12)=2027),IF(AND(MONTH(S12)=3,YEAR(S12)=2027),"●","▶"),IF(AND(MONTH(S12)=3,YEAR(S12)=2027),"◀","─")),"") | O12: =IF(AND(R12<=DATE(2027,4,1),S12>=DATE(2027,4,1)),IF(AND(MONTH(R12)=4,YEAR(R12)=2027),IF(AND(MONTH(S12)=4,YEAR(S12)=2027),"●","▶"),IF(AND(MONTH(S12)=4,YEAR(S12)=2027),"◀","─")),"") | P12: =IF(AND(R12<=DATE(2027,5,1),S12>=DATE(2027,5,1)),IF(AND(MONTH(R12)=5,YEAR(R12)=2027),IF(AND(MONTH(S12)=5,YEAR(S12)=2027),"●","▶"),IF(AND(MONTH(S12)=5,YEAR(S12)=2027),"◀","─")),"") | Q12: =IF(AND(R12<=DATE(2027,6,1),S12>=DATE(2027,6,1)),IF(AND(MONTH(R12)=6,YEAR(R12)=2027),IF(AND(MONTH(S12)=6,YEAR(S12)=2027),"●","▶"),IF(AND(MONTH(S12)=6,YEAR(S12)=2027),"◀","─")),"") | R12: =EDATE($C$2,-6) -> 46312 | S12: =EDATE($C$2,-4) -> 46373 | T12: 3
B13: 預訂婚禮攝影師 | C13: 雙 | D13: =IF(AND(R13<=DATE(2026,5,1),S13>=DATE(2026,5,1)),IF(AND(MONTH(R13)=5,YEAR(R13)=2026),IF(AND(MONTH(S13)=5,YEAR(S13)=2026),"●","▶"),IF(AND(MONTH(S13)=5,YEAR(S13)=2026),"◀","─")),"") | E13: =IF(AND(R13<=DATE(2026,6,1),S13>=DATE(2026,6,1)),IF(AND(MONTH(R13)=6,YEAR(R13)=2026),IF(AND(MONTH(S13)=6,YEAR(S13)=2026),"●","▶"),IF(AND(MONTH(S13)=6,YEAR(S13)=2026),"◀","─")),"") | F13: =IF(AND(R13<=DATE(2026,7,1),S13>=DATE(2026,7,1)),IF(AND(MONTH(R13)=7,YEAR(R13)=2026),IF(AND(MONTH(S13)=7,YEAR(S13)=2026),"●","▶"),IF(AND(MONTH(S13)=7,YEAR(S13)=2026),"◀","─")),"") | G13: =IF(AND(R13<=DATE(2026,8,1),S13>=DATE(2026,8,1)),IF(AND(MONTH(R13)=8,YEAR(R13)=2026),IF(AND(MONTH(S13)=8,YEAR(S13)=2026),"●","▶"),IF(AND(MONTH(S13)=8,YEAR(S13)=2026),"◀","─")),"") | H13: =IF(AND(R13<=DATE(2026,9,1),S13>=DATE(2026,9,1)),IF(AND(MONTH(R13)=9,YEAR(R13)=2026),IF(AND(MONTH(S13)=9,YEAR(S13)=2026),"●","▶"),IF(AND(MONTH(S13)=9,YEAR(S13)=2026),"◀","─")),"") | I13: =IF(AND(R13<=DATE(2026,10,1),S13>=DATE(2026,10,1)),IF(AND(MONTH(R13)=10,YEAR(R13)=2026),IF(AND(MONTH(S13)=10,YEAR(S13)=2026),"●","▶"),IF(AND(MONTH(S13)=10,YEAR(S13)=2026),"◀","─")),"") | J13: =IF(AND(R13<=DATE(2026,11,1),S13>=DATE(2026,11,1)),IF(AND(MONTH(R13)=11,YEAR(R13)=2026),IF(AND(MONTH(S13)=11,YEAR(S13)=2026),"●","▶"),IF(AND(MONTH(S13)=11,YEAR(S13)=2026),"◀","─")),"") -> ─ | K13: =IF(AND(R13<=DATE(2026,12,1),S13>=DATE(2026,12,1)),IF(AND(MONTH(R13)=12,YEAR(R13)=2026),IF(AND(MONTH(S13)=12,YEAR(S13)=2026),"●","▶"),IF(AND(MONTH(S13)=12,YEAR(S13)=2026),"◀","─")),"") -> ─ | L13: =IF(AND(R13<=DATE(2027,1,1),S13>=DATE(2027,1,1)),IF(AND(MONTH(R13)=1,YEAR(R13)=2027),IF(AND(MONTH(S13)=1,YEAR(S13)=2027),"●","▶"),IF(AND(MONTH(S13)=1,YEAR(S13)=2027),"◀","─")),"") -> ◀ | M13: =IF(AND(R13<=DATE(2027,2,1),S13>=DATE(2027,2,1)),IF(AND(MONTH(R13)=2,YEAR(R13)=2027),IF(AND(MONTH(S13)=2,YEAR(S13)=2027),"●","▶"),IF(AND(MONTH(S13)=2,YEAR(S13)=2027),"◀","─")),"") | N13: =IF(AND(R13<=DATE(2027,3,1),S13>=DATE(2027,3,1)),IF(AND(MONTH(R13)=3,YEAR(R13)=2027),IF(AND(MONTH(S13)=3,YEAR(S13)=2027),"●","▶"),IF(AND(MONTH(S13)=3,YEAR(S13)=2027),"◀","─")),"") | O13: =IF(AND(R13<=DATE(2027,4,1),S13>=DATE(2027,4,1)),IF(AND(MONTH(R13)=4,YEAR(R13)=2027),IF(AND(MONTH(S13)=4,YEAR(S13)=2027),"●","▶"),IF(AND(MONTH(S13)=4,YEAR(S13)=2027),"◀","─")),"") | P13: =IF(AND(R13<=DATE(2027,5,1),S13>=DATE(2027,5,1)),IF(AND(MONTH(R13)=5,YEAR(R13)=2027),IF(AND(MONTH(S13)=5,YEAR(S13)=2027),"●","▶"),IF(AND(MONTH(S13)=5,YEAR(S13)=2027),"◀","─")),"") | Q13: =IF(AND(R13<=DATE(2027,6,1),S13>=DATE(2027,6,1)),IF(AND(MONTH(R13)=6,YEAR(R13)=2027),IF(AND(MONTH(S13)=6,YEAR(S13)=2027),"●","▶"),IF(AND(MONTH(S13)=6,YEAR(S13)=2027),"◀","─")),"") | R13: =EDATE($C$2,-6) -> 46312 | S13: =EDATE($C$2,-3) -> 46404 | T13: 3
B14: 預訂婚禮錄影（選配） | C14: 雙 | D14: =IF(AND(R14<=DATE(2026,5,1),S14>=DATE(2026,5,1)),IF(AND(MONTH(R14)=5,YEAR(R14)=2026),IF(AND(MONTH(S14)=5,YEAR(S14)=2026),"●","▶"),IF(AND(MONTH(S14)=5,YEAR(S14)=2026),"◀","─")),"") | E14: =IF(AND(R14<=DATE(2026,6,1),S14>=DATE(2026,6,1)),IF(AND(MONTH(R14)=6,YEAR(R14)=2026),IF(AND(MONTH(S14)=6,YEAR(S14)=2026),"●","▶"),IF(AND(MONTH(S14)=6,YEAR(S14)=2026),"◀","─")),"") | F14: =IF(AND(R14<=DATE(2026,7,1),S14>=DATE(2026,7,1)),IF(AND(MONTH(R14)=7,YEAR(R14)=2026),IF(AND(MONTH(S14)=7,YEAR(S14)=2026),"●","▶"),IF(AND(MONTH(S14)=7,YEAR(S14)=2026),"◀","─")),"") | G14: =IF(AND(R14<=DATE(2026,8,1),S14>=DATE(2026,8,1)),IF(AND(MONTH(R14)=8,YEAR(R14)=2026),IF(AND(MONTH(S14)=8,YEAR(S14)=2026),"●","▶"),IF(AND(MONTH(S14)=8,YEAR(S14)=2026),"◀","─")),"") | H14: =IF(AND(R14<=DATE(2026,9,1),S14>=DATE(2026,9,1)),IF(AND(MONTH(R14)=9,YEAR(R14)=2026),IF(AND(MONTH(S14)=9,YEAR(S14)=2026),"●","▶"),IF(AND(MONTH(S14)=9,YEAR(S14)=2026),"◀","─")),"") | I14: =IF(AND(R14<=DATE(2026,10,1),S14>=DATE(2026,10,1)),IF(AND(MONTH(R14)=10,YEAR(R14)=2026),IF(AND(MONTH(S14)=10,YEAR(S14)=2026),"●","▶"),IF(AND(MONTH(S14)=10,YEAR(S14)=2026),"◀","─")),"") | J14: =IF(AND(R14<=DATE(2026,11,1),S14>=DATE(2026,11,1)),IF(AND(MONTH(R14)=11,YEAR(R14)=2026),IF(AND(MONTH(S14)=11,YEAR(S14)=2026),"●","▶"),IF(AND(MONTH(S14)=11,YEAR(S14)=2026),"◀","─")),"") -> ─ | K14: =IF(AND(R14<=DATE(2026,12,1),S14>=DATE(2026,12,1)),IF(AND(MONTH(R14)=12,YEAR(R14)=2026),IF(AND(MONTH(S14)=12,YEAR(S14)=2026),"●","▶"),IF(AND(MONTH(S14)=12,YEAR(S14)=2026),"◀","─")),"") -> ─ | L14: =IF(AND(R14<=DATE(2027,1,1),S14>=DATE(2027,1,1)),IF(AND(MONTH(R14)=1,YEAR(R14)=2027),IF(AND(MONTH(S14)=1,YEAR(S14)=2027),"●","▶"),IF(AND(MONTH(S14)=1,YEAR(S14)=2027),"◀","─")),"") -> ◀ | M14: =IF(AND(R14<=DATE(2027,2,1),S14>=DATE(2027,2,1)),IF(AND(MONTH(R14)=2,YEAR(R14)=2027),IF(AND(MONTH(S14)=2,YEAR(S14)=2027),"●","▶"),IF(AND(MONTH(S14)=2,YEAR(S14)=2027),"◀","─")),"") | N14: =IF(AND(R14<=DATE(2027,3,1),S14>=DATE(2027,3,1)),IF(AND(MONTH(R14)=3,YEAR(R14)=2027),IF(AND(MONTH(S14)=3,YEAR(S14)=2027),"●","▶"),IF(AND(MONTH(S14)=3,YEAR(S14)=2027),"◀","─")),"") | O14: =IF(AND(R14<=DATE(2027,4,1),S14>=DATE(2027,4,1)),IF(AND(MONTH(R14)=4,YEAR(R14)=2027),IF(AND(MONTH(S14)=4,YEAR(S14)=2027),"●","▶"),IF(AND(MONTH(S14)=4,YEAR(S14)=2027),"◀","─")),"") | P14: =IF(AND(R14<=DATE(2027,5,1),S14>=DATE(2027,5,1)),IF(AND(MONTH(R14)=5,YEAR(R14)=2027),IF(AND(MONTH(S14)=5,YEAR(S14)=2027),"●","▶"),IF(AND(MONTH(S14)=5,YEAR(S14)=2027),"◀","─")),"") | Q14: =IF(AND(R14<=DATE(2027,6,1),S14>=DATE(2027,6,1)),IF(AND(MONTH(R14)=6,YEAR(R14)=2027),IF(AND(MONTH(S14)=6,YEAR(S14)=2027),"●","▶"),IF(AND(MONTH(S14)=6,YEAR(S14)=2027),"◀","─")),"") | R14: =EDATE($C$2,-6) -> 46312 | S14: =EDATE($C$2,-3) -> 46404 | T14: 3
B15: 預訂新娘秘書（新秘）⚡ | C15: 女 | D15: =IF(AND(R15<=DATE(2026,5,1),S15>=DATE(2026,5,1)),IF(AND(MONTH(R15)=5,YEAR(R15)=2026),IF(AND(MONTH(S15)=5,YEAR(S15)=2026),"●","▶"),IF(AND(MONTH(S15)=5,YEAR(S15)=2026),"◀","─")),"") | E15: =IF(AND(R15<=DATE(2026,6,1),S15>=DATE(2026,6,1)),IF(AND(MONTH(R15)=6,YEAR(R15)=2026),IF(AND(MONTH(S15)=6,YEAR(S15)=2026),"●","▶"),IF(AND(MONTH(S15)=6,YEAR(S15)=2026),"◀","─")),"") | F15: =IF(AND(R15<=DATE(2026,7,1),S15>=DATE(2026,7,1)),IF(AND(MONTH(R15)=7,YEAR(R15)=2026),IF(AND(MONTH(S15)=7,YEAR(S15)=2026),"●","▶"),IF(AND(MONTH(S15)=7,YEAR(S15)=2026),"◀","─")),"") | G15: =IF(AND(R15<=DATE(2026,8,1),S15>=DATE(2026,8,1)),IF(AND(MONTH(R15)=8,YEAR(R15)=2026),IF(AND(MONTH(S15)=8,YEAR(S15)=2026),"●","▶"),IF(AND(MONTH(S15)=8,YEAR(S15)=2026),"◀","─")),"") | H15: =IF(AND(R15<=DATE(2026,9,1),S15>=DATE(2026,9,1)),IF(AND(MONTH(R15)=9,YEAR(R15)=2026),IF(AND(MONTH(S15)=9,YEAR(S15)=2026),"●","▶"),IF(AND(MONTH(S15)=9,YEAR(S15)=2026),"◀","─")),"") | I15: =IF(AND(R15<=DATE(2026,10,1),S15>=DATE(2026,10,1)),IF(AND(MONTH(R15)=10,YEAR(R15)=2026),IF(AND(MONTH(S15)=10,YEAR(S15)=2026),"●","▶"),IF(AND(MONTH(S15)=10,YEAR(S15)=2026),"◀","─")),"") | J15: =IF(AND(R15<=DATE(2026,11,1),S15>=DATE(2026,11,1)),IF(AND(MONTH(R15)=11,YEAR(R15)=2026),IF(AND(MONTH(S15)=11,YEAR(S15)=2026),"●","▶"),IF(AND(MONTH(S15)=11,YEAR(S15)=2026),"◀","─")),"") -> ─ | K15: =IF(AND(R15<=DATE(2026,12,1),S15>=DATE(2026,12,1)),IF(AND(MONTH(R15)=12,YEAR(R15)=2026),IF(AND(MONTH(S15)=12,YEAR(S15)=2026),"●","▶"),IF(AND(MONTH(S15)=12,YEAR(S15)=2026),"◀","─")),"") -> ─ | L15: =IF(AND(R15<=DATE(2027,1,1),S15>=DATE(2027,1,1)),IF(AND(MONTH(R15)=1,YEAR(R15)=2027),IF(AND(MONTH(S15)=1,YEAR(S15)=2027),"●","▶"),IF(AND(MONTH(S15)=1,YEAR(S15)=2027),"◀","─")),"") -> ◀ | M15: =IF(AND(R15<=DATE(2027,2,1),S15>=DATE(2027,2,1)),IF(AND(MONTH(R15)=2,YEAR(R15)=2027),IF(AND(MONTH(S15)=2,YEAR(S15)=2027),"●","▶"),IF(AND(MONTH(S15)=2,YEAR(S15)=2027),"◀","─")),"") | N15: =IF(AND(R15<=DATE(2027,3,1),S15>=DATE(2027,3,1)),IF(AND(MONTH(R15)=3,YEAR(R15)=2027),IF(AND(MONTH(S15)=3,YEAR(S15)=2027),"●","▶"),IF(AND(MONTH(S15)=3,YEAR(S15)=2027),"◀","─")),"") | O15: =IF(AND(R15<=DATE(2027,4,1),S15>=DATE(2027,4,1)),IF(AND(MONTH(R15)=4,YEAR(R15)=2027),IF(AND(MONTH(S15)=4,YEAR(S15)=2027),"●","▶"),IF(AND(MONTH(S15)=4,YEAR(S15)=2027),"◀","─")),"") | P15: =IF(AND(R15<=DATE(2027,5,1),S15>=DATE(2027,5,1)),IF(AND(MONTH(R15)=5,YEAR(R15)=2027),IF(AND(MONTH(S15)=5,YEAR(S15)=2027),"●","▶"),IF(AND(MONTH(S15)=5,YEAR(S15)=2027),"◀","─")),"") | Q15: =IF(AND(R15<=DATE(2027,6,1),S15>=DATE(2027,6,1)),IF(AND(MONTH(R15)=6,YEAR(R15)=2027),IF(AND(MONTH(S15)=6,YEAR(S15)=2027),"●","▶"),IF(AND(MONTH(S15)=6,YEAR(S15)=2027),"◀","─")),"") | R15: =EDATE($C$2,-6) -> 46312 | S15: =EDATE($C$2,-3) -> 46404 | T15: 2
B16: 確定婚禮主持人 | C16: 雙 | D16: =IF(AND(R16<=DATE(2026,5,1),S16>=DATE(2026,5,1)),IF(AND(MONTH(R16)=5,YEAR(R16)=2026),IF(AND(MONTH(S16)=5,YEAR(S16)=2026),"●","▶"),IF(AND(MONTH(S16)=5,YEAR(S16)=2026),"◀","─")),"") | E16: =IF(AND(R16<=DATE(2026,6,1),S16>=DATE(2026,6,1)),IF(AND(MONTH(R16)=6,YEAR(R16)=2026),IF(AND(MONTH(S16)=6,YEAR(S16)=2026),"●","▶"),IF(AND(MONTH(S16)=6,YEAR(S16)=2026),"◀","─")),"") | F16: =IF(AND(R16<=DATE(2026,7,1),S16>=DATE(2026,7,1)),IF(AND(MONTH(R16)=7,YEAR(R16)=2026),IF(AND(MONTH(S16)=7,YEAR(S16)=2026),"●","▶"),IF(AND(MONTH(S16)=7,YEAR(S16)=2026),"◀","─")),"") | G16: =IF(AND(R16<=DATE(2026,8,1),S16>=DATE(2026,8,1)),IF(AND(MONTH(R16)=8,YEAR(R16)=2026),IF(AND(MONTH(S16)=8,YEAR(S16)=2026),"●","▶"),IF(AND(MONTH(S16)=8,YEAR(S16)=2026),"◀","─")),"") | H16: =IF(AND(R16<=DATE(2026,9,1),S16>=DATE(2026,9,1)),IF(AND(MONTH(R16)=9,YEAR(R16)=2026),IF(AND(MONTH(S16)=9,YEAR(S16)=2026),"●","▶"),IF(AND(MONTH(S16)=9,YEAR(S16)=2026),"◀","─")),"") | I16: =IF(AND(R16<=DATE(2026,10,1),S16>=DATE(2026,10,1)),IF(AND(MONTH(R16)=10,YEAR(R16)=2026),IF(AND(MONTH(S16)=10,YEAR(S16)=2026),"●","▶"),IF(AND(MONTH(S16)=10,YEAR(S16)=2026),"◀","─")),"") | J16: =IF(AND(R16<=DATE(2026,11,1),S16>=DATE(2026,11,1)),IF(AND(MONTH(R16)=11,YEAR(R16)=2026),IF(AND(MONTH(S16)=11,YEAR(S16)=2026),"●","▶"),IF(AND(MONTH(S16)=11,YEAR(S16)=2026),"◀","─")),"") | K16: =IF(AND(R16<=DATE(2026,12,1),S16>=DATE(2026,12,1)),IF(AND(MONTH(R16)=12,YEAR(R16)=2026),IF(AND(MONTH(S16)=12,YEAR(S16)=2026),"●","▶"),IF(AND(MONTH(S16)=12,YEAR(S16)=2026),"◀","─")),"") -> ─ | L16: =IF(AND(R16<=DATE(2027,1,1),S16>=DATE(2027,1,1)),IF(AND(MONTH(R16)=1,YEAR(R16)=2027),IF(AND(MONTH(S16)=1,YEAR(S16)=2027),"●","▶"),IF(AND(MONTH(S16)=1,YEAR(S16)=2027),"◀","─")),"") -> ◀ | M16: =IF(AND(R16<=DATE(2027,2,1),S16>=DATE(2027,2,1)),IF(AND(MONTH(R16)=2,YEAR(R16)=2027),IF(AND(MONTH(S16)=2,YEAR(S16)=2027),"●","▶"),IF(AND(MONTH(S16)=2,YEAR(S16)=2027),"◀","─")),"") | N16: =IF(AND(R16<=DATE(2027,3,1),S16>=DATE(2027,3,1)),IF(AND(MONTH(R16)=3,YEAR(R16)=2027),IF(AND(MONTH(S16)=3,YEAR(S16)=2027),"●","▶"),IF(AND(MONTH(S16)=3,YEAR(S16)=2027),"◀","─")),"") | O16: =IF(AND(R16<=DATE(2027,4,1),S16>=DATE(2027,4,1)),IF(AND(MONTH(R16)=4,YEAR(R16)=2027),IF(AND(MONTH(S16)=4,YEAR(S16)=2027),"●","▶"),IF(AND(MONTH(S16)=4,YEAR(S16)=2027),"◀","─")),"") | P16: =IF(AND(R16<=DATE(2027,5,1),S16>=DATE(2027,5,1)),IF(AND(MONTH(R16)=5,YEAR(R16)=2027),IF(AND(MONTH(S16)=5,YEAR(S16)=2027),"●","▶"),IF(AND(MONTH(S16)=5,YEAR(S16)=2027),"◀","─")),"") | Q16: =IF(AND(R16<=DATE(2027,6,1),S16>=DATE(2027,6,1)),IF(AND(MONTH(R16)=6,YEAR(R16)=2027),IF(AND(MONTH(S16)=6,YEAR(S16)=2027),"●","▶"),IF(AND(MONTH(S16)=6,YEAR(S16)=2027),"◀","─")),"") | R16: =EDATE($C$2,-5) -> 46343 | S16: =EDATE($C$2,-3) -> 46404 | T16: 3
B17: 規劃蜜月行程 | C17: 雙 | D17: =IF(AND(R17<=DATE(2026,5,1),S17>=DATE(2026,5,1)),IF(AND(MONTH(R17)=5,YEAR(R17)=2026),IF(AND(MONTH(S17)=5,YEAR(S17)=2026),"●","▶"),IF(AND(MONTH(S17)=5,YEAR(S17)=2026),"◀","─")),"") | E17: =IF(AND(R17<=DATE(2026,6,1),S17>=DATE(2026,6,1)),IF(AND(MONTH(R17)=6,YEAR(R17)=2026),IF(AND(MONTH(S17)=6,YEAR(S17)=2026),"●","▶"),IF(AND(MONTH(S17)=6,YEAR(S17)=2026),"◀","─")),"") | F17: =IF(AND(R17<=DATE(2026,7,1),S17>=DATE(2026,7,1)),IF(AND(MONTH(R17)=7,YEAR(R17)=2026),IF(AND(MONTH(S17)=7,YEAR(S17)=2026),"●","▶"),IF(AND(MONTH(S17)=7,YEAR(S17)=2026),"◀","─")),"") | G17: =IF(AND(R17<=DATE(2026,8,1),S17>=DATE(2026,8,1)),IF(AND(MONTH(R17)=8,YEAR(R17)=2026),IF(AND(MONTH(S17)=8,YEAR(S17)=2026),"●","▶"),IF(AND(MONTH(S17)=8,YEAR(S17)=2026),"◀","─")),"") | H17: =IF(AND(R17<=DATE(2026,9,1),S17>=DATE(2026,9,1)),IF(AND(MONTH(R17)=9,YEAR(R17)=2026),IF(AND(MONTH(S17)=9,YEAR(S17)=2026),"●","▶"),IF(AND(MONTH(S17)=9,YEAR(S17)=2026),"◀","─")),"") | I17: =IF(AND(R17<=DATE(2026,10,1),S17>=DATE(2026,10,1)),IF(AND(MONTH(R17)=10,YEAR(R17)=2026),IF(AND(MONTH(S17)=10,YEAR(S17)=2026),"●","▶"),IF(AND(MONTH(S17)=10,YEAR(S17)=2026),"◀","─")),"") | J17: =IF(AND(R17<=DATE(2026,11,1),S17>=DATE(2026,11,1)),IF(AND(MONTH(R17)=11,YEAR(R17)=2026),IF(AND(MONTH(S17)=11,YEAR(S17)=2026),"●","▶"),IF(AND(MONTH(S17)=11,YEAR(S17)=2026),"◀","─")),"") | K17: =IF(AND(R17<=DATE(2026,12,1),S17>=DATE(2026,12,1)),IF(AND(MONTH(R17)=12,YEAR(R17)=2026),IF(AND(MONTH(S17)=12,YEAR(S17)=2026),"●","▶"),IF(AND(MONTH(S17)=12,YEAR(S17)=2026),"◀","─")),"") -> ─ | L17: =IF(AND(R17<=DATE(2027,1,1),S17>=DATE(2027,1,1)),IF(AND(MONTH(R17)=1,YEAR(R17)=2027),IF(AND(MONTH(S17)=1,YEAR(S17)=2027),"●","▶"),IF(AND(MONTH(S17)=1,YEAR(S17)=2027),"◀","─")),"") -> ─ | M17: =IF(AND(R17<=DATE(2027,2,1),S17>=DATE(2027,2,1)),IF(AND(MONTH(R17)=2,YEAR(R17)=2027),IF(AND(MONTH(S17)=2,YEAR(S17)=2027),"●","▶"),IF(AND(MONTH(S17)=2,YEAR(S17)=2027),"◀","─")),"") -> ◀ | N17: =IF(AND(R17<=DATE(2027,3,1),S17>=DATE(2027,3,1)),IF(AND(MONTH(R17)=3,YEAR(R17)=2027),IF(AND(MONTH(S17)=3,YEAR(S17)=2027),"●","▶"),IF(AND(MONTH(S17)=3,YEAR(S17)=2027),"◀","─")),"") | O17: =IF(AND(R17<=DATE(2027,4,1),S17>=DATE(2027,4,1)),IF(AND(MONTH(R17)=4,YEAR(R17)=2027),IF(AND(MONTH(S17)=4,YEAR(S17)=2027),"●","▶"),IF(AND(MONTH(S17)=4,YEAR(S17)=2027),"◀","─")),"") | P17: =IF(AND(R17<=DATE(2027,5,1),S17>=DATE(2027,5,1)),IF(AND(MONTH(R17)=5,YEAR(R17)=2027),IF(AND(MONTH(S17)=5,YEAR(S17)=2027),"●","▶"),IF(AND(MONTH(S17)=5,YEAR(S17)=2027),"◀","─")),"") | Q17: =IF(AND(R17<=DATE(2027,6,1),S17>=DATE(2027,6,1)),IF(AND(MONTH(R17)=6,YEAR(R17)=2027),IF(AND(MONTH(S17)=6,YEAR(S17)=2027),"●","▶"),IF(AND(MONTH(S17)=6,YEAR(S17)=2027),"◀","─")),"") | R17: =EDATE($C$2,-5) -> 46343 | S17: =EDATE($C$2,-2) -> 46435 | T17: 3
A18: 法律文件 | B18: 準備結婚登記文件 | C18: 雙 | D18: =IF(AND(R18<=DATE(2026,5,1),S18>=DATE(2026,5,1)),IF(AND(MONTH(R18)=5,YEAR(R18)=2026),IF(AND(MONTH(S18)=5,YEAR(S18)=2026),"●","▶"),IF(AND(MONTH(S18)=5,YEAR(S18)=2026),"◀","─")),"") | E18: =IF(AND(R18<=DATE(2026,6,1),S18>=DATE(2026,6,1)),IF(AND(MONTH(R18)=6,YEAR(R18)=2026),IF(AND(MONTH(S18)=6,YEAR(S18)=2026),"●","▶"),IF(AND(MONTH(S18)=6,YEAR(S18)=2026),"◀","─")),"") | F18: =IF(AND(R18<=DATE(2026,7,1),S18>=DATE(2026,7,1)),IF(AND(MONTH(R18)=7,YEAR(R18)=2026),IF(AND(MONTH(S18)=7,YEAR(S18)=2026),"●","▶"),IF(AND(MONTH(S18)=7,YEAR(S18)=2026),"◀","─")),"") | G18: =IF(AND(R18<=DATE(2026,8,1),S18>=DATE(2026,8,1)),IF(AND(MONTH(R18)=8,YEAR(R18)=2026),IF(AND(MONTH(S18)=8,YEAR(S18)=2026),"●","▶"),IF(AND(MONTH(S18)=8,YEAR(S18)=2026),"◀","─")),"") | H18: =IF(AND(R18<=DATE(2026,9,1),S18>=DATE(2026,9,1)),IF(AND(MONTH(R18)=9,YEAR(R18)=2026),IF(AND(MONTH(S18)=9,YEAR(S18)=2026),"●","▶"),IF(AND(MONTH(S18)=9,YEAR(S18)=2026),"◀","─")),"") | I18: =IF(AND(R18<=DATE(2026,10,1),S18>=DATE(2026,10,1)),IF(AND(MONTH(R18)=10,YEAR(R18)=2026),IF(AND(MONTH(S18)=10,YEAR(S18)=2026),"●","▶"),IF(AND(MONTH(S18)=10,YEAR(S18)=2026),"◀","─")),"") | J18: =IF(AND(R18<=DATE(2026,11,1),S18>=DATE(2026,11,1)),IF(AND(MONTH(R18)=11,YEAR(R18)=2026),IF(AND(MONTH(S18)=11,YEAR(S18)=2026),"●","▶"),IF(AND(MONTH(S18)=11,YEAR(S18)=2026),"◀","─")),"") | K18: =IF(AND(R18<=DATE(2026,12,1),S18>=DATE(2026,12,1)),IF(AND(MONTH(R18)=12,YEAR(R18)=2026),IF(AND(MONTH(S18)=12,YEAR(S18)=2026),"●","▶"),IF(AND(MONTH(S18)=12,YEAR(S18)=2026),"◀","─")),"") | L18: =IF(AND(R18<=DATE(2027,1,1),S18>=DATE(2027,1,1)),IF(AND(MONTH(R18)=1,YEAR(R18)=2027),IF(AND(MONTH(S18)=1,YEAR(S18)=2027),"●","▶"),IF(AND(MONTH(S18)=1,YEAR(S18)=2027),"◀","─")),"") -> ─ | M18: =IF(AND(R18<=DATE(2027,2,1),S18>=DATE(2027,2,1)),IF(AND(MONTH(R18)=2,YEAR(R18)=2027),IF(AND(MONTH(S18)=2,YEAR(S18)=2027),"●","▶"),IF(AND(MONTH(S18)=2,YEAR(S18)=2027),"◀","─")),"") -> ─ | N18: =IF(AND(R18<=DATE(2027,3,1),S18>=DATE(2027,3,1)),IF(AND(MONTH(R18)=3,YEAR(R18)=2027),IF(AND(MONTH(S18)=3,YEAR(S18)=2027),"●","▶"),IF(AND(MONTH(S18)=3,YEAR(S18)=2027),"◀","─")),"") -> ◀ | O18: =IF(AND(R18<=DATE(2027,4,1),S18>=DATE(2027,4,1)),IF(AND(MONTH(R18)=4,YEAR(R18)=2027),IF(AND(MONTH(S18)=4,YEAR(S18)=2027),"●","▶"),IF(AND(MONTH(S18)=4,YEAR(S18)=2027),"◀","─")),"") | P18: =IF(AND(R18<=DATE(2027,5,1),S18>=DATE(2027,5,1)),IF(AND(MONTH(R18)=5,YEAR(R18)=2027),IF(AND(MONTH(S18)=5,YEAR(S18)=2027),"●","▶"),IF(AND(MONTH(S18)=5,YEAR(S18)=2027),"◀","─")),"") | Q18: =IF(AND(R18<=DATE(2027,6,1),S18>=DATE(2027,6,1)),IF(AND(MONTH(R18)=6,YEAR(R18)=2027),IF(AND(MONTH(S18)=6,YEAR(S18)=2027),"●","▶"),IF(AND(MONTH(S18)=6,YEAR(S18)=2027),"◀","─")),"") | R18: =EDATE($C$2,-4) -> 46373 | S18: =EDATE($C$2,-1) -> 46463 | T18: 3
B19: 辦理結婚登記（戶政事務所） | C19: 雙 | D19: =IF(AND(R19<=DATE(2026,5,1),S19>=DATE(2026,5,1)),IF(AND(MONTH(R19)=5,YEAR(R19)=2026),IF(AND(MONTH(S19)=5,YEAR(S19)=2026),"●","▶"),IF(AND(MONTH(S19)=5,YEAR(S19)=2026),"◀","─")),"") | E19: =IF(AND(R19<=DATE(2026,6,1),S19>=DATE(2026,6,1)),IF(AND(MONTH(R19)=6,YEAR(R19)=2026),IF(AND(MONTH(S19)=6,YEAR(S19)=2026),"●","▶"),IF(AND(MONTH(S19)=6,YEAR(S19)=2026),"◀","─")),"") | F19: =IF(AND(R19<=DATE(2026,7,1),S19>=DATE(2026,7,1)),IF(AND(MONTH(R19)=7,YEAR(R19)=2026),IF(AND(MONTH(S19)=7,YEAR(S19)=2026),"●","▶"),IF(AND(MONTH(S19)=7,YEAR(S19)=2026),"◀","─")),"") | G19: =IF(AND(R19<=DATE(2026,8,1),S19>=DATE(2026,8,1)),IF(AND(MONTH(R19)=8,YEAR(R19)=2026),IF(AND(MONTH(S19)=8,YEAR(S19)=2026),"●","▶"),IF(AND(MONTH(S19)=8,YEAR(S19)=2026),"◀","─")),"") | H19: =IF(AND(R19<=DATE(2026,9,1),S19>=DATE(2026,9,1)),IF(AND(MONTH(R19)=9,YEAR(R19)=2026),IF(AND(MONTH(S19)=9,YEAR(S19)=2026),"●","▶"),IF(AND(MONTH(S19)=9,YEAR(S19)=2026),"◀","─")),"") | I19: =IF(AND(R19<=DATE(2026,10,1),S19>=DATE(2026,10,1)),IF(AND(MONTH(R19)=10,YEAR(R19)=2026),IF(AND(MONTH(S19)=10,YEAR(S19)=2026),"●","▶"),IF(AND(MONTH(S19)=10,YEAR(S19)=2026),"◀","─")),"") | J19: =IF(AND(R19<=DATE(2026,11,1),S19>=DATE(2026,11,1)),IF(AND(MONTH(R19)=11,YEAR(R19)=2026),IF(AND(MONTH(S19)=11,YEAR(S19)=2026),"●","▶"),IF(AND(MONTH(S19)=11,YEAR(S19)=2026),"◀","─")),"") | K19: =IF(AND(R19<=DATE(2026,12,1),S19>=DATE(2026,12,1)),IF(AND(MONTH(R19)=12,YEAR(R19)=2026),IF(AND(MONTH(S19)=12,YEAR(S19)=2026),"●","▶"),IF(AND(MONTH(S19)=12,YEAR(S19)=2026),"◀","─")),"") | L19: =IF(AND(R19<=DATE(2027,1,1),S19>=DATE(2027,1,1)),IF(AND(MONTH(R19)=1,YEAR(R19)=2027),IF(AND(MONTH(S19)=1,YEAR(S19)=2027),"●","▶"),IF(AND(MONTH(S19)=1,YEAR(S19)=2027),"◀","─")),"") | M19: =IF(AND(R19<=DATE(2027,2,1),S19>=DATE(2027,2,1)),IF(AND(MONTH(R19)=2,YEAR(R19)=2027),IF(AND(MONTH(S19)=2,YEAR(S19)=2027),"●","▶"),IF(AND(MONTH(S19)=2,YEAR(S19)=2027),"◀","─")),"") | N19: =IF(AND(R19<=DATE(2027,3,1),S19>=DATE(2027,3,1)),IF(AND(MONTH(R19)=3,YEAR(R19)=2027),IF(AND(MONTH(S19)=3,YEAR(S19)=2027),"●","▶"),IF(AND(MONTH(S19)=3,YEAR(S19)=2027),"◀","─")),"") | O19: =IF(AND(R19<=DATE(2027,4,1),S19>=DATE(2027,4,1)),IF(AND(MONTH(R19)=4,YEAR(R19)=2027),IF(AND(MONTH(S19)=4,YEAR(S19)=2027),"●","▶"),IF(AND(MONTH(S19)=4,YEAR(S19)=2027),"◀","─")),"") -> ◀ | P19: =IF(AND(R19<=DATE(2027,5,1),S19>=DATE(2027,5,1)),IF(AND(MONTH(R19)=5,YEAR(R19)=2027),IF(AND(MONTH(S19)=5,YEAR(S19)=2027),"●","▶"),IF(AND(MONTH(S19)=5,YEAR(S19)=2027),"◀","─")),"") | Q19: =IF(AND(R19<=DATE(2027,6,1),S19>=DATE(2027,6,1)),IF(AND(MONTH(R19)=6,YEAR(R19)=2027),IF(AND(MONTH(S19)=6,YEAR(S19)=2027),"●","▶"),IF(AND(MONTH(S19)=6,YEAR(S19)=2027),"◀","─")),"") | R19: =EDATE($C$2,-1) -> 46463 | S19: =EDATE($C$2,0) -> 46494 | T19: 3
A20: 男方準備 | B20: 確認聘金金額 | C20: 男 | D20: =IF(AND(R20<=DATE(2026,5,1),S20>=DATE(2026,5,1)),IF(AND(MONTH(R20)=5,YEAR(R20)=2026),IF(AND(MONTH(S20)=5,YEAR(S20)=2026),"●","▶"),IF(AND(MONTH(S20)=5,YEAR(S20)=2026),"◀","─")),"") | E20: =IF(AND(R20<=DATE(2026,6,1),S20>=DATE(2026,6,1)),IF(AND(MONTH(R20)=6,YEAR(R20)=2026),IF(AND(MONTH(S20)=6,YEAR(S20)=2026),"●","▶"),IF(AND(MONTH(S20)=6,YEAR(S20)=2026),"◀","─")),"") | F20: =IF(AND(R20<=DATE(2026,7,1),S20>=DATE(2026,7,1)),IF(AND(MONTH(R20)=7,YEAR(R20)=2026),IF(AND(MONTH(S20)=7,YEAR(S20)=2026),"●","▶"),IF(AND(MONTH(S20)=7,YEAR(S20)=2026),"◀","─")),"") | G20: =IF(AND(R20<=DATE(2026,8,1),S20>=DATE(2026,8,1)),IF(AND(MONTH(R20)=8,YEAR(R20)=2026),IF(AND(MONTH(S20)=8,YEAR(S20)=2026),"●","▶"),IF(AND(MONTH(S20)=8,YEAR(S20)=2026),"◀","─")),"") | H20: =IF(AND(R20<=DATE(2026,9,1),S20>=DATE(2026,9,1)),IF(AND(MONTH(R20)=9,YEAR(R20)=2026),IF(AND(MONTH(S20)=9,YEAR(S20)=2026),"●","▶"),IF(AND(MONTH(S20)=9,YEAR(S20)=2026),"◀","─")),"") | I20: =IF(AND(R20<=DATE(2026,10,1),S20>=DATE(2026,10,1)),IF(AND(MONTH(R20)=10,YEAR(R20)=2026),IF(AND(MONTH(S20)=10,YEAR(S20)=2026),"●","▶"),IF(AND(MONTH(S20)=10,YEAR(S20)=2026),"◀","─")),"") | J20: =IF(AND(R20<=DATE(2026,11,1),S20>=DATE(2026,11,1)),IF(AND(MONTH(R20)=11,YEAR(R20)=2026),IF(AND(MONTH(S20)=11,YEAR(S20)=2026),"●","▶"),IF(AND(MONTH(S20)=11,YEAR(S20)=2026),"◀","─")),"") -> ─ | K20: =IF(AND(R20<=DATE(2026,12,1),S20>=DATE(2026,12,1)),IF(AND(MONTH(R20)=12,YEAR(R20)=2026),IF(AND(MONTH(S20)=12,YEAR(S20)=2026),"●","▶"),IF(AND(MONTH(S20)=12,YEAR(S20)=2026),"◀","─")),"") -> ◀ | L20: =IF(AND(R20<=DATE(2027,1,1),S20>=DATE(2027,1,1)),IF(AND(MONTH(R20)=1,YEAR(R20)=2027),IF(AND(MONTH(S20)=1,YEAR(S20)=2027),"●","▶"),IF(AND(MONTH(S20)=1,YEAR(S20)=2027),"◀","─")),"") | M20: =IF(AND(R20<=DATE(2027,2,1),S20>=DATE(2027,2,1)),IF(AND(MONTH(R20)=2,YEAR(R20)=2027),IF(AND(MONTH(S20)=2,YEAR(S20)=2027),"●","▶"),IF(AND(MONTH(S20)=2,YEAR(S20)=2027),"◀","─")),"") | N20: =IF(AND(R20<=DATE(2027,3,1),S20>=DATE(2027,3,1)),IF(AND(MONTH(R20)=3,YEAR(R20)=2027),IF(AND(MONTH(S20)=3,YEAR(S20)=2027),"●","▶"),IF(AND(MONTH(S20)=3,YEAR(S20)=2027),"◀","─")),"") | O20: =IF(AND(R20<=DATE(2027,4,1),S20>=DATE(2027,4,1)),IF(AND(MONTH(R20)=4,YEAR(R20)=2027),IF(AND(MONTH(S20)=4,YEAR(S20)=2027),"●","▶"),IF(AND(MONTH(S20)=4,YEAR(S20)=2027),"◀","─")),"") | P20: =IF(AND(R20<=DATE(2027,5,1),S20>=DATE(2027,5,1)),IF(AND(MONTH(R20)=5,YEAR(R20)=2027),IF(AND(MONTH(S20)=5,YEAR(S20)=2027),"●","▶"),IF(AND(MONTH(S20)=5,YEAR(S20)=2027),"◀","─")),"") | Q20: =IF(AND(R20<=DATE(2027,6,1),S20>=DATE(2027,6,1)),IF(AND(MONTH(R20)=6,YEAR(R20)=2027),IF(AND(MONTH(S20)=6,YEAR(S20)=2027),"●","▶"),IF(AND(MONTH(S20)=6,YEAR(S20)=2027),"◀","─")),"") | R20: =EDATE($C$2,-6) -> 46312 | S20: =EDATE($C$2,-4) -> 46373 | T20: 1
B21: 準備聘禮（禮餅等） | C21: 男 | D21: =IF(AND(R21<=DATE(2026,5,1),S21>=DATE(2026,5,1)),IF(AND(MONTH(R21)=5,YEAR(R21)=2026),IF(AND(MONTH(S21)=5,YEAR(S21)=2026),"●","▶"),IF(AND(MONTH(S21)=5,YEAR(S21)=2026),"◀","─")),"") | E21: =IF(AND(R21<=DATE(2026,6,1),S21>=DATE(2026,6,1)),IF(AND(MONTH(R21)=6,YEAR(R21)=2026),IF(AND(MONTH(S21)=6,YEAR(S21)=2026),"●","▶"),IF(AND(MONTH(S21)=6,YEAR(S21)=2026),"◀","─")),"") | F21: =IF(AND(R21<=DATE(2026,7,1),S21>=DATE(2026,7,1)),IF(AND(MONTH(R21)=7,YEAR(R21)=2026),IF(AND(MONTH(S21)=7,YEAR(S21)=2026),"●","▶"),IF(AND(MONTH(S21)=7,YEAR(S21)=2026),"◀","─")),"") | G21: =IF(AND(R21<=DATE(2026,8,1),S21>=DATE(2026,8,1)),IF(AND(MONTH(R21)=8,YEAR(R21)=2026),IF(AND(MONTH(S21)=8,YEAR(S21)=2026),"●","▶"),IF(AND(MONTH(S21)=8,YEAR(S21)=2026),"◀","─")),"") | H21: =IF(AND(R21<=DATE(2026,9,1),S21>=DATE(2026,9,1)),IF(AND(MONTH(R21)=9,YEAR(R21)=2026),IF(AND(MONTH(S21)=9,YEAR(S21)=2026),"●","▶"),IF(AND(MONTH(S21)=9,YEAR(S21)=2026),"◀","─")),"") | I21: =IF(AND(R21<=DATE(2026,10,1),S21>=DATE(2026,10,1)),IF(AND(MONTH(R21)=10,YEAR(R21)=2026),IF(AND(MONTH(S21)=10,YEAR(S21)=2026),"●","▶"),IF(AND(MONTH(S21)=10,YEAR(S21)=2026),"◀","─")),"") | J21: =IF(AND(R21<=DATE(2026,11,1),S21>=DATE(2026,11,1)),IF(AND(MONTH(R21)=11,YEAR(R21)=2026),IF(AND(MONTH(S21)=11,YEAR(S21)=2026),"●","▶"),IF(AND(MONTH(S21)=11,YEAR(S21)=2026),"◀","─")),"") | K21: =IF(AND(R21<=DATE(2026,12,1),S21>=DATE(2026,12,1)),IF(AND(MONTH(R21)=12,YEAR(R21)=2026),IF(AND(MONTH(S21)=12,YEAR(S21)=2026),"●","▶"),IF(AND(MONTH(S21)=12,YEAR(S21)=2026),"◀","─")),"") | L21: =IF(AND(R21<=DATE(2027,1,1),S21>=DATE(2027,1,1)),IF(AND(MONTH(R21)=1,YEAR(R21)=2027),IF(AND(MONTH(S21)=1,YEAR(S21)=2027),"●","▶"),IF(AND(MONTH(S21)=1,YEAR(S21)=2027),"◀","─")),"") | M21: =IF(AND(R21<=DATE(2027,2,1),S21>=DATE(2027,2,1)),IF(AND(MONTH(R21)=2,YEAR(R21)=2027),IF(AND(MONTH(S21)=2,YEAR(S21)=2027),"●","▶"),IF(AND(MONTH(S21)=2,YEAR(S21)=2027),"◀","─")),"") -> ─ | N21: =IF(AND(R21<=DATE(2027,3,1),S21>=DATE(2027,3,1)),IF(AND(MONTH(R21)=3,YEAR(R21)=2027),IF(AND(MONTH(S21)=3,YEAR(S21)=2027),"●","▶"),IF(AND(MONTH(S21)=3,YEAR(S21)=2027),"◀","─")),"") -> ◀ | O21: =IF(AND(R21<=DATE(2027,4,1),S21>=DATE(2027,4,1)),IF(AND(MONTH(R21)=4,YEAR(R21)=2027),IF(AND(MONTH(S21)=4,YEAR(S21)=2027),"●","▶"),IF(AND(MONTH(S21)=4,YEAR(S21)=2027),"◀","─")),"") | P21: =IF(AND(R21<=DATE(2027,5,1),S21>=DATE(2027,5,1)),IF(AND(MONTH(R21)=5,YEAR(R21)=2027),IF(AND(MONTH(S21)=5,YEAR(S21)=2027),"●","▶"),IF(AND(MONTH(S21)=5,YEAR(S21)=2027),"◀","─")),"") | Q21: =IF(AND(R21<=DATE(2027,6,1),S21>=DATE(2027,6,1)),IF(AND(MONTH(R21)=6,YEAR(R21)=2027),IF(AND(MONTH(S21)=6,YEAR(S21)=2027),"●","▶"),IF(AND(MONTH(S21)=6,YEAR(S21)=2027),"◀","─")),"") | R21: =EDATE($C$2,-3) -> 46404 | S21: =EDATE($C$2,-1) -> 46463 | T21: 1
B22: 購買結婚對戒 | C22: 男 | D22: =IF(AND(R22<=DATE(2026,5,1),S22>=DATE(2026,5,1)),IF(AND(MONTH(R22)=5,YEAR(R22)=2026),IF(AND(MONTH(S22)=5,YEAR(S22)=2026),"●","▶"),IF(AND(MONTH(S22)=5,YEAR(S22)=2026),"◀","─")),"") | E22: =IF(AND(R22<=DATE(2026,6,1),S22>=DATE(2026,6,1)),IF(AND(MONTH(R22)=6,YEAR(R22)=2026),IF(AND(MONTH(S22)=6,YEAR(S22)=2026),"●","▶"),IF(AND(MONTH(S22)=6,YEAR(S22)=2026),"◀","─")),"") | F22: =IF(AND(R22<=DATE(2026,7,1),S22>=DATE(2026,7,1)),IF(AND(MONTH(R22)=7,YEAR(R22)=2026),IF(AND(MONTH(S22)=7,YEAR(S22)=2026),"●","▶"),IF(AND(MONTH(S22)=7,YEAR(S22)=2026),"◀","─")),"") | G22: =IF(AND(R22<=DATE(2026,8,1),S22>=DATE(2026,8,1)),IF(AND(MONTH(R22)=8,YEAR(R22)=2026),IF(AND(MONTH(S22)=8,YEAR(S22)=2026),"●","▶"),IF(AND(MONTH(S22)=8,YEAR(S22)=2026),"◀","─")),"") | H22: =IF(AND(R22<=DATE(2026,9,1),S22>=DATE(2026,9,1)),IF(AND(MONTH(R22)=9,YEAR(R22)=2026),IF(AND(MONTH(S22)=9,YEAR(S22)=2026),"●","▶"),IF(AND(MONTH(S22)=9,YEAR(S22)=2026),"◀","─")),"") | I22: =IF(AND(R22<=DATE(2026,10,1),S22>=DATE(2026,10,1)),IF(AND(MONTH(R22)=10,YEAR(R22)=2026),IF(AND(MONTH(S22)=10,YEAR(S22)=2026),"●","▶"),IF(AND(MONTH(S22)=10,YEAR(S22)=2026),"◀","─")),"") | J22: =IF(AND(R22<=DATE(2026,11,1),S22>=DATE(2026,11,1)),IF(AND(MONTH(R22)=11,YEAR(R22)=2026),IF(AND(MONTH(S22)=11,YEAR(S22)=2026),"●","▶"),IF(AND(MONTH(S22)=11,YEAR(S22)=2026),"◀","─")),"") | K22: =IF(AND(R22<=DATE(2026,12,1),S22>=DATE(2026,12,1)),IF(AND(MONTH(R22)=12,YEAR(R22)=2026),IF(AND(MONTH(S22)=12,YEAR(S22)=2026),"●","▶"),IF(AND(MONTH(S22)=12,YEAR(S22)=2026),"◀","─")),"") -> ─ | L22: =IF(AND(R22<=DATE(2027,1,1),S22>=DATE(2027,1,1)),IF(AND(MONTH(R22)=1,YEAR(R22)=2027),IF(AND(MONTH(S22)=1,YEAR(S22)=2027),"●","▶"),IF(AND(MONTH(S22)=1,YEAR(S22)=2027),"◀","─")),"") -> ─ | M22: =IF(AND(R22<=DATE(2027,2,1),S22>=DATE(2027,2,1)),IF(AND(MONTH(R22)=2,YEAR(R22)=2027),IF(AND(MONTH(S22)=2,YEAR(S22)=2027),"●","▶"),IF(AND(MONTH(S22)=2,YEAR(S22)=2027),"◀","─")),"") -> ◀ | N22: =IF(AND(R22<=DATE(2027,3,1),S22>=DATE(2027,3,1)),IF(AND(MONTH(R22)=3,YEAR(R22)=2027),IF(AND(MONTH(S22)=3,YEAR(S22)=2027),"●","▶"),IF(AND(MONTH(S22)=3,YEAR(S22)=2027),"◀","─")),"") | O22: =IF(AND(R22<=DATE(2027,4,1),S22>=DATE(2027,4,1)),IF(AND(MONTH(R22)=4,YEAR(R22)=2027),IF(AND(MONTH(S22)=4,YEAR(S22)=2027),"●","▶"),IF(AND(MONTH(S22)=4,YEAR(S22)=2027),"◀","─")),"") | P22: =IF(AND(R22<=DATE(2027,5,1),S22>=DATE(2027,5,1)),IF(AND(MONTH(R22)=5,YEAR(R22)=2027),IF(AND(MONTH(S22)=5,YEAR(S22)=2027),"●","▶"),IF(AND(MONTH(S22)=5,YEAR(S22)=2027),"◀","─")),"") | Q22: =IF(AND(R22<=DATE(2027,6,1),S22>=DATE(2027,6,1)),IF(AND(MONTH(R22)=6,YEAR(R22)=2027),IF(AND(MONTH(S22)=6,YEAR(S22)=2027),"●","▶"),IF(AND(MONTH(S22)=6,YEAR(S22)=2027),"◀","─")),"") | R22: =EDATE($C$2,-5) -> 46343 | S22: =EDATE($C$2,-2) -> 46435 | T22: 1
B23: 準備西裝/禮服 | C23: 男 | D23: =IF(AND(R23<=DATE(2026,5,1),S23>=DATE(2026,5,1)),IF(AND(MONTH(R23)=5,YEAR(R23)=2026),IF(AND(MONTH(S23)=5,YEAR(S23)=2026),"●","▶"),IF(AND(MONTH(S23)=5,YEAR(S23)=2026),"◀","─")),"") | E23: =IF(AND(R23<=DATE(2026,6,1),S23>=DATE(2026,6,1)),IF(AND(MONTH(R23)=6,YEAR(R23)=2026),IF(AND(MONTH(S23)=6,YEAR(S23)=2026),"●","▶"),IF(AND(MONTH(S23)=6,YEAR(S23)=2026),"◀","─")),"") | F23: =IF(AND(R23<=DATE(2026,7,1),S23>=DATE(2026,7,1)),IF(AND(MONTH(R23)=7,YEAR(R23)=2026),IF(AND(MONTH(S23)=7,YEAR(S23)=2026),"●","▶"),IF(AND(MONTH(S23)=7,YEAR(S23)=2026),"◀","─")),"") | G23: =IF(AND(R23<=DATE(2026,8,1),S23>=DATE(2026,8,1)),IF(AND(MONTH(R23)=8,YEAR(R23)=2026),IF(AND(MONTH(S23)=8,YEAR(S23)=2026),"●","▶"),IF(AND(MONTH(S23)=8,YEAR(S23)=2026),"◀","─")),"") | H23: =IF(AND(R23<=DATE(2026,9,1),S23>=DATE(2026,9,1)),IF(AND(MONTH(R23)=9,YEAR(R23)=2026),IF(AND(MONTH(S23)=9,YEAR(S23)=2026),"●","▶"),IF(AND(MONTH(S23)=9,YEAR(S23)=2026),"◀","─")),"") | I23: =IF(AND(R23<=DATE(2026,10,1),S23>=DATE(2026,10,1)),IF(AND(MONTH(R23)=10,YEAR(R23)=2026),IF(AND(MONTH(S23)=10,YEAR(S23)=2026),"●","▶"),IF(AND(MONTH(S23)=10,YEAR(S23)=2026),"◀","─")),"") | J23: =IF(AND(R23<=DATE(2026,11,1),S23>=DATE(2026,11,1)),IF(AND(MONTH(R23)=11,YEAR(R23)=2026),IF(AND(MONTH(S23)=11,YEAR(S23)=2026),"●","▶"),IF(AND(MONTH(S23)=11,YEAR(S23)=2026),"◀","─")),"") | K23: =IF(AND(R23<=DATE(2026,12,1),S23>=DATE(2026,12,1)),IF(AND(MONTH(R23)=12,YEAR(R23)=2026),IF(AND(MONTH(S23)=12,YEAR(S23)=2026),"●","▶"),IF(AND(MONTH(S23)=12,YEAR(S23)=2026),"◀","─")),"") | L23: =IF(AND(R23<=DATE(2027,1,1),S23>=DATE(2027,1,1)),IF(AND(MONTH(R23)=1,YEAR(R23)=2027),IF(AND(MONTH(S23)=1,YEAR(S23)=2027),"●","▶"),IF(AND(MONTH(S23)=1,YEAR(S23)=2027),"◀","─")),"") | M23: =IF(AND(R23<=DATE(2027,2,1),S23>=DATE(2027,2,1)),IF(AND(MONTH(R23)=2,YEAR(R23)=2027),IF(AND(MONTH(S23)=2,YEAR(S23)=2027),"●","▶"),IF(AND(MONTH(S23)=2,YEAR(S23)=2027),"◀","─")),"") | N23: =IF(AND(R23<=DATE(2027,3,1),S23>=DATE(2027,3,1)),IF(AND(MONTH(R23)=3,YEAR(R23)=2027),IF(AND(MONTH(S23)=3,YEAR(S23)=2027),"●","▶"),IF(AND(MONTH(S23)=3,YEAR(S23)=2027),"◀","─")),"") -> ◀ | O23: =IF(AND(R23<=DATE(2027,4,1),S23>=DATE(2027,4,1)),IF(AND(MONTH(R23)=4,YEAR(R23)=2027),IF(AND(MONTH(S23)=4,YEAR(S23)=2027),"●","▶"),IF(AND(MONTH(S23)=4,YEAR(S23)=2027),"◀","─")),"") | P23: =IF(AND(R23<=DATE(2027,5,1),S23>=DATE(2027,5,1)),IF(AND(MONTH(R23)=5,YEAR(R23)=2027),IF(AND(MONTH(S23)=5,YEAR(S23)=2027),"●","▶"),IF(AND(MONTH(S23)=5,YEAR(S23)=2027),"◀","─")),"") | Q23: =IF(AND(R23<=DATE(2027,6,1),S23>=DATE(2027,6,1)),IF(AND(MONTH(R23)=6,YEAR(R23)=2027),IF(AND(MONTH(S23)=6,YEAR(S23)=2027),"●","▶"),IF(AND(MONTH(S23)=6,YEAR(S23)=2027),"◀","─")),"") | R23: =EDATE($C$2,-2) -> 46435 | S23: =EDATE($C$2,-1) -> 46463 | T23: 1
B24: 婚房布置規劃 | C24: 男 | D24: =IF(AND(R24<=DATE(2026,5,1),S24>=DATE(2026,5,1)),IF(AND(MONTH(R24)=5,YEAR(R24)=2026),IF(AND(MONTH(S24)=5,YEAR(S24)=2026),"●","▶"),IF(AND(MONTH(S24)=5,YEAR(S24)=2026),"◀","─")),"") | E24: =IF(AND(R24<=DATE(2026,6,1),S24>=DATE(2026,6,1)),IF(AND(MONTH(R24)=6,YEAR(R24)=2026),IF(AND(MONTH(S24)=6,YEAR(S24)=2026),"●","▶"),IF(AND(MONTH(S24)=6,YEAR(S24)=2026),"◀","─")),"") | F24: =IF(AND(R24<=DATE(2026,7,1),S24>=DATE(2026,7,1)),IF(AND(MONTH(R24)=7,YEAR(R24)=2026),IF(AND(MONTH(S24)=7,YEAR(S24)=2026),"●","▶"),IF(AND(MONTH(S24)=7,YEAR(S24)=2026),"◀","─")),"") | G24: =IF(AND(R24<=DATE(2026,8,1),S24>=DATE(2026,8,1)),IF(AND(MONTH(R24)=8,YEAR(R24)=2026),IF(AND(MONTH(S24)=8,YEAR(S24)=2026),"●","▶"),IF(AND(MONTH(S24)=8,YEAR(S24)=2026),"◀","─")),"") | H24: =IF(AND(R24<=DATE(2026,9,1),S24>=DATE(2026,9,1)),IF(AND(MONTH(R24)=9,YEAR(R24)=2026),IF(AND(MONTH(S24)=9,YEAR(S24)=2026),"●","▶"),IF(AND(MONTH(S24)=9,YEAR(S24)=2026),"◀","─")),"") | I24: =IF(AND(R24<=DATE(2026,10,1),S24>=DATE(2026,10,1)),IF(AND(MONTH(R24)=10,YEAR(R24)=2026),IF(AND(MONTH(S24)=10,YEAR(S24)=2026),"●","▶"),IF(AND(MONTH(S24)=10,YEAR(S24)=2026),"◀","─")),"") | J24: =IF(AND(R24<=DATE(2026,11,1),S24>=DATE(2026,11,1)),IF(AND(MONTH(R24)=11,YEAR(R24)=2026),IF(AND(MONTH(S24)=11,YEAR(S24)=2026),"●","▶"),IF(AND(MONTH(S24)=11,YEAR(S24)=2026),"◀","─")),"") | K24: =IF(AND(R24<=DATE(2026,12,1),S24>=DATE(2026,12,1)),IF(AND(MONTH(R24)=12,YEAR(R24)=2026),IF(AND(MONTH(S24)=12,YEAR(S24)=2026),"●","▶"),IF(AND(MONTH(S24)=12,YEAR(S24)=2026),"◀","─")),"") | L24: =IF(AND(R24<=DATE(2027,1,1),S24>=DATE(2027,1,1)),IF(AND(MONTH(R24)=1,YEAR(R24)=2027),IF(AND(MONTH(S24)=1,YEAR(S24)=2027),"●","▶"),IF(AND(MONTH(S24)=1,YEAR(S24)=2027),"◀","─")),"") | M24: =IF(AND(R24<=DATE(2027,2,1),S24>=DATE(2027,2,1)),IF(AND(MONTH(R24)=2,YEAR(R24)=2027),IF(AND(MONTH(S24)=2,YEAR(S24)=2027),"●","▶"),IF(AND(MONTH(S24)=2,YEAR(S24)=2027),"◀","─")),"") -> ─ | N24: =IF(AND(R24<=DATE(2027,3,1),S24>=DATE(2027,3,1)),IF(AND(MONTH(R24)=3,YEAR(R24)=2027),IF(AND(MONTH(S24)=3,YEAR(S24)=2027),"●","▶"),IF(AND(MONTH(S24)=3,YEAR(S24)=2027),"◀","─")),"") -> ◀ | O24: =IF(AND(R24<=DATE(2027,4,1),S24>=DATE(2027,4,1)),IF(AND(MONTH(R24)=4,YEAR(R24)=2027),IF(AND(MONTH(S24)=4,YEAR(S24)=2027),"●","▶"),IF(AND(MONTH(S24)=4,YEAR(S24)=2027),"◀","─")),"") | P24: =IF(AND(R24<=DATE(2027,5,1),S24>=DATE(2027,5,1)),IF(AND(MONTH(R24)=5,YEAR(R24)=2027),IF(AND(MONTH(S24)=5,YEAR(S24)=2027),"●","▶"),IF(AND(MONTH(S24)=5,YEAR(S24)=2027),"◀","─")),"") | Q24: =IF(AND(R24<=DATE(2027,6,1),S24>=DATE(2027,6,1)),IF(AND(MONTH(R24)=6,YEAR(R24)=2027),IF(AND(MONTH(S24)=6,YEAR(S24)=2027),"●","▶"),IF(AND(MONTH(S24)=6,YEAR(S24)=2027),"◀","─")),"") | R24: =EDATE($C$2,-3) -> 46404 | S24: =EDATE($C$2,-1) -> 46463 | T24: 1
B25: 安排迎娶車隊 | C25: 男 | D25: =IF(AND(R25<=DATE(2026,5,1),S25>=DATE(2026,5,1)),IF(AND(MONTH(R25)=5,YEAR(R25)=2026),IF(AND(MONTH(S25)=5,YEAR(S25)=2026),"●","▶"),IF(AND(MONTH(S25)=5,YEAR(S25)=2026),"◀","─")),"") | E25: =IF(AND(R25<=DATE(2026,6,1),S25>=DATE(2026,6,1)),IF(AND(MONTH(R25)=6,YEAR(R25)=2026),IF(AND(MONTH(S25)=6,YEAR(S25)=2026),"●","▶"),IF(AND(MONTH(S25)=6,YEAR(S25)=2026),"◀","─")),"") | F25: =IF(AND(R25<=DATE(2026,7,1),S25>=DATE(2026,7,1)),IF(AND(MONTH(R25)=7,YEAR(R25)=2026),IF(AND(MONTH(S25)=7,YEAR(S25)=2026),"●","▶"),IF(AND(MONTH(S25)=7,YEAR(S25)=2026),"◀","─")),"") | G25: =IF(AND(R25<=DATE(2026,8,1),S25>=DATE(2026,8,1)),IF(AND(MONTH(R25)=8,YEAR(R25)=2026),IF(AND(MONTH(S25)=8,YEAR(S25)=2026),"●","▶"),IF(AND(MONTH(S25)=8,YEAR(S25)=2026),"◀","─")),"") | H25: =IF(AND(R25<=DATE(2026,9,1),S25>=DATE(2026,9,1)),IF(AND(MONTH(R25)=9,YEAR(R25)=2026),IF(AND(MONTH(S25)=9,YEAR(S25)=2026),"●","▶"),IF(AND(MONTH(S25)=9,YEAR(S25)=2026),"◀","─")),"") | I25: =IF(AND(R25<=DATE(2026,10,1),S25>=DATE(2026,10,1)),IF(AND(MONTH(R25)=10,YEAR(R25)=2026),IF(AND(MONTH(S25)=10,YEAR(S25)=2026),"●","▶"),IF(AND(MONTH(S25)=10,YEAR(S25)=2026),"◀","─")),"") | J25: =IF(AND(R25<=DATE(2026,11,1),S25>=DATE(2026,11,1)),IF(AND(MONTH(R25)=11,YEAR(R25)=2026),IF(AND(MONTH(S25)=11,YEAR(S25)=2026),"●","▶"),IF(AND(MONTH(S25)=11,YEAR(S25)=2026),"◀","─")),"") | K25: =IF(AND(R25<=DATE(2026,12,1),S25>=DATE(2026,12,1)),IF(AND(MONTH(R25)=12,YEAR(R25)=2026),IF(AND(MONTH(S25)=12,YEAR(S25)=2026),"●","▶"),IF(AND(MONTH(S25)=12,YEAR(S25)=2026),"◀","─")),"") | L25: =IF(AND(R25<=DATE(2027,1,1),S25>=DATE(2027,1,1)),IF(AND(MONTH(R25)=1,YEAR(R25)=2027),IF(AND(MONTH(S25)=1,YEAR(S25)=2027),"●","▶"),IF(AND(MONTH(S25)=1,YEAR(S25)=2027),"◀","─")),"") | M25: =IF(AND(R25<=DATE(2027,2,1),S25>=DATE(2027,2,1)),IF(AND(MONTH(R25)=2,YEAR(R25)=2027),IF(AND(MONTH(S25)=2,YEAR(S25)=2027),"●","▶"),IF(AND(MONTH(S25)=2,YEAR(S25)=2027),"◀","─")),"") | N25: =IF(AND(R25<=DATE(2027,3,1),S25>=DATE(2027,3,1)),IF(AND(MONTH(R25)=3,YEAR(R25)=2027),IF(AND(MONTH(S25)=3,YEAR(S25)=2027),"●","▶"),IF(AND(MONTH(S25)=3,YEAR(S25)=2027),"◀","─")),"") -> ◀ | O25: =IF(AND(R25<=DATE(2027,4,1),S25>=DATE(2027,4,1)),IF(AND(MONTH(R25)=4,YEAR(R25)=2027),IF(AND(MONTH(S25)=4,YEAR(S25)=2027),"●","▶"),IF(AND(MONTH(S25)=4,YEAR(S25)=2027),"◀","─")),"") | P25: =IF(AND(R25<=DATE(2027,5,1),S25>=DATE(2027,5,1)),IF(AND(MONTH(R25)=5,YEAR(R25)=2027),IF(AND(MONTH(S25)=5,YEAR(S25)=2027),"●","▶"),IF(AND(MONTH(S25)=5,YEAR(S25)=2027),"◀","─")),"") | Q25: =IF(AND(R25<=DATE(2027,6,1),S25>=DATE(2027,6,1)),IF(AND(MONTH(R25)=6,YEAR(R25)=2027),IF(AND(MONTH(S25)=6,YEAR(S25)=2027),"●","▶"),IF(AND(MONTH(S25)=6,YEAR(S25)=2027),"◀","─")),"") | R25: =EDATE($C$2,-2) -> 46435 | S25: =EDATE($C$2,-1) -> 46463 | T25: 1
